Workbook
Name APG_ave: '2025_stats_lakers'!$X$1:$X$25
Name FGper_Ave: '2025_stats_lakers'!$J$1:$J$25
Name Luka_PTS: Luka_24_25_Regular_Playoffs[PTS]
Name Luka_TRB: Luka_24_25_Regular_Playoffs[TRB]
Name PTS: '2025_stats_lakers'!$AD$1:$AD$25
Name PTS_ave: '2025_stats_lakers'!$AD$1:$AD$25
Name RPG_ave: '2025_stats_lakers'!$W$1:$W$25
Name STOCK_ave: '2025_stats_lakers'!$AA$1:$AA$25
Name test: Luka_24_25_Regular_Playoffs!$W$4
Name Threes_ave: '2025_stats_lakers'!$M$1:$M$25

Sheet Cover
F1: JAYVEE LAKERS MINI ANALYTICS
F8: Data sourced from: Basketball-Reference.com – Lakers 2024-25 Stats 🔗 https://www.basketball-reference.com/teams/LAL/2025.html
F10: Luka 2025 Stats (Dallas vs. Lakers)
F14: Lebron and Reaves Statistics Before Vs. After Luka joining
F18: Player Statistics (Regular Season)

Sheet Luka_2025_Stats_Mavs_Vs_Lakers
G1: Luka Doncic 2025 Stats
E5: When he was on Mavs | J5: When he is on Lakers
O8: There is no significant difference when Luka was playing on the Mavs and when he was traded to the Lakers
E9: PTS | F9: =AVERAGEIF(Luka_24_25_Regular_Playoffs!E:E,"DAL",Luka_24_25_Regular_Playoffs!AG2:AG84) -> 28.142857 | J9: PPG | K9: =AVERAGEIF(Luka_24_25_Regular_Playoffs!E2:E93,"LAL",Luka_24_25_Regular_Playoffs!AG:AG) -> 28.178571
E12: REB | F12: =AVERAGEIF(Luka_24_25_Regular_Playoffs!E:E,"DAL",Luka_24_25_Regular_Playoffs!AA2:AA84) -> 8.2380952 | J12: REB | K12: =AVERAGEIF(Luka_24_25_Regular_Playoffs!E:E,"LAL",Luka_24_25_Regular_Playoffs!AA:AA) -> 8.0714286
E15: AST | F15: =AVERAGEIF(Luka_24_25_Regular_Playoffs!E2:E93,"DAL",Luka_24_25_Regular_Playoffs!AB1:AB84) -> 7.8181818 | J15: AST | K15: =AVERAGEIF(Luka_24_25_Regular_Playoffs!E2:E93,"LAL",Luka_24_25_Regular_Playoffs!AB2:AB93) -> 7.5357143
E18: FG% | F18: =AVERAGEIF(Luka_24_25_Regular_Playoffs!E:E,"DAL",Luka_24_25_Regular_Playoffs!N:N) -> 0.46481818 | J18: FG% | K18: =AVERAGEIF(Luka_24_25_Regular_Playoffs!E2:E93,"LAL",Luka_24_25_Regular_Playoffs!N2:N93) -> 0.43628571

Sheet Lebron&Reaves_Before&After_Luka
F1: Does Lebron and Reaves productivity lessen when Luka arrived?
C6: BEFORE LUKA | J6: AFTER LUKA
C9: PLAYERS | D9: PPG | E9: RPG | F9: APG | G9: FGA | H9: FG% | J9: PLAYERS | K9: PPG | L9: RPG | M9: APG | N9: FGA | O9: FG%
C10: Lebron James | D10: =AVERAGEIF(Lebron_regular_Playoffs[Column1],"No Luka",Lebron_regular_Playoffs!AH1:AH82) -> 24.270833 | E10: =AVERAGEIF(Lebron_regular_Playoffs[Column1],"No Luka",Lebron_regular_Playoffs!AB1:AB82) -> 7.6875 | F10: =AVERAGEIF(Lebron_regular_Playoffs[Column1],"No Luka",Lebron_regular_Playoffs!AC1:AC82) -> 9.0625 | G10: =AVERAGEIF(Lebron_regular_Playoffs[Column1],"No Luka",Lebron_regular_Playoffs!N1:N82) -> 18.145833 | H10: =AVERAGEIF(Lebron_regular_Playoffs[Column1],"No Luka",Lebron_regular_Playoffs!O1:O82) -> 0.51360417 | J10: Lebron James | K10: =AVERAGEIF(Lebron_regular_Playoffs[Column1],"Luka",Lebron_regular_Playoffs!AH1:AH82) -> 24.772727 | L10: =AVERAGEIF(Lebron_regular_Playoffs[Column1],"Luka",Lebron_regular_Playoffs!AB1:AB82) -> 8.0454545 | M10: =AVERAGEIF(Lebron_regular_Playoffs[Column1],"Luka",Lebron_regular_Playoffs!AC1:AC82) -> 6.3636364 | N10: =AVERAGEIF(Lebron_regular_Playoffs[Column1],"Luka",Lebron_regular_Playoffs!N1:N82) -> 18.136364 | O10: =AVERAGEIF(Lebron_regular_Playoffs[Column1],"Luka",Lebron_regular_Playoffs!O1:O82) -> 0.50513636
C11: Austin Reaves | D11: =AVERAGEIF('AR_REG_OFFS '!C:C,"No Luka",'AR_REG_OFFS '!AG1:AG82) -> 19.595745 | E11: =AVERAGEIF('AR_REG_OFFS '!C:C,"No Luka",'AR_REG_OFFS '!AA1:AA82) -> 4.3404255 | F11: =AVERAGEIF('AR_REG_OFFS '!C:C,"No Luka",'AR_REG_OFFS '!AB1:AB82) -> 6.0851064 | G11: =AVERAGEIF('AR_REG_OFFS '!C:C,"No Luka",'AR_REG_OFFS '!M1:M82) -> 14.191489 | H11: =AVERAGEIF('AR_REG_OFFS '!C:C,"No Luka",'AR_REG_OFFS '!N1:N82) -> 0.45448936 | J11: Austin Reaves | K11: =AVERAGEIF('AR_REG_OFFS '!C:C,"Luka",'AR_REG_OFFS '!AG1:AG82) -> 21.307692 | L11: =AVERAGEIF('AR_REG_OFFS '!C:C,"Luka",'AR_REG_OFFS '!AA1:AA82) -> 4.8076923 | M11: =AVERAGEIF('AR_REG_OFFS '!C:C,"Luka",'AR_REG_OFFS '!AB1:AB82) -> 5.1923077 | N11: =AVERAGEIF('AR_REG_OFFS '!C:C,"Luka",'AR_REG_OFFS '!M1:M82) -> 14.230769 | O11: =AVERAGEIF('AR_REG_OFFS '!C:C,"Luka",'AR_REG_OFFS '!N1:N82) -> 0.47084615
F14: This shows that there is no significant difference in terms of production when Reaves and Bron played when Luka arrived to LA.

Sheet Laker_Player_Statistics
A1: 2025 Lakers Player Statistics
C5: LeBron James
A9: PPG | D9: RPG | G9: APG
A10: =VLOOKUP(C5,'2025_stats_lakers'!AG1:AN25,7,FALSE) -> 24.4 | D10: =VLOOKUP(C5,'2025_stats_lakers'!AG1:AN25,4,FALSE) -> 7.8 | G10: =VLOOKUP(C5,'2025_stats_lakers'!AG1:AN25,5,FALSE) -> 8.2
A14: FG% | D14: 3P% | G14: Awards
A15: =VLOOKUP(C5,'2025_stats_lakers'!AG1:AO25,2,FALSE) -> 0.513 | D15: =VLOOKUP(C5,'2025_stats_lakers'!AG1:AO25,3,FALSE) -> 0.376 | G15: =VLOOKUP(C5,'2025_stats_lakers'!AG1:AO25,8,FALSE) -> MVP-6,CPOY-7,AS,NBA2

Sheet Player_PPG
A3: Row Labels | B3: PPG
A4: Jaxson Hayes | B4: 6.8
A5: Dorian Finney-Smith | B5: 7.9
A6: Max Christie | B6: 8.5
A7: Dalton Knecht | B7: 9.1
A8: D'Angelo Russell | B8: 12.4
A9: Rui Hachimura | B9: 13.1
A10: Austin Reaves | B10: 20.2
A11: LeBron James | B11: 24.4
A12: Anthony Davis | B12: 25.7
A13: Luka Dončić | B13: 28.2
A14: Grand Total | B14: 15.63

Sheet Player_STOCKS
A3: Row Labels | B3: Average of STOCKS
A4: Rui Hachimura | B4: 0.6
A5: Cam Reddish | B5: 0.65
A6: Jarred Vanderbilt | B6: 0.65
A7: Max Christie | B7: 0.65
A8: Jordan Goodwin | B8: 0.7
A9: Austin Reaves | B9: 0.7
A10: Jaxson Hayes | B10: 0.75
A11: LeBron James | B11: 0.8
A12: Luka Dončić | B12: 1
A13: Anthony Davis | B13: 1.7
A14: Grand Total | B14: 0.82

Sheet 2025_stats_lakers
A1: Rk | B1: Player | C1: Age | D1: Pos | E1: G | F1: GS | G1: MP | H1: FG | I1: FGA | J1: FG% | K1: 3P | L1: 3PA | M1: 3P% | N1: 2P | O1: 2PA | P1: 2P% | Q1: eFG% | R1: FT | S1: FTA | T1: FT% | U1: ORB | V1: DRB | W1: TRB | X1: AST | Y1: STL | Z1: BLK | AA1: STOCKS | AB1: TOV | AC1: PF | AD1: PTS | AE1: Awards | AG1: Player | AH1: FG% | AI1: 3P% | AJ1: TRB | AK1: AST | AL1: STOCKS | AM1: PTS | AN1: Awards
A2: 1 | B2: Luka Dončić | C2: 25 | D2: PG | E2: 28 | F2: 28 | G2: 35.1 | H2: 8.8 | I2: 20 | J2: 0.438 | K2: 3.6 | L2: 9.6 | M2: 0.379 | N2: 5.1 | O2: 10.4 | P2: 0.493 | Q2: 0.53 | R2: 7 | S2: 8.9 | T2: 0.791 | U2: 0.9 | V2: 7.2 | W2: 8.1 | X2: 7.5 | Y2: 1.6 | Z2: 0.4 | AA2: =SUM(Worksheet[[#This Row],[STL]:[BLK]])/2 -> 1 | AB2: 3.7 | AC2: 2.4 | AD2: 28.2 | AG2: Luka Dončić | AH2: 0.438 | AI2: 0.379 | AJ2: 8.1 | AK2: 7.5 | AL2: 1 | AM2: 28.2
A3: 2 | B3: Austin Reaves | C3: 26 | D3: SG | E3: 73 | F3: 73 | G3: 34.9 | H3: 6.5 | I3: 14.2 | J3: 0.46 | K3: 2.7 | L3: 7.3 | M3: 0.377 | N3: 3.8 | O3: 6.9 | P3: 0.547 | Q3: 0.556 | R3: 4.4 | S3: 5 | T3: 0.877 | U3: 0.8 | V3: 3.7 | W3: 4.5 | X3: 5.8 | Y3: 1.1 | Z3: 0.3 | AA3: =SUM(Worksheet[[#This Row],[STL]:[BLK]])/2 -> 0.7 | AB3: 2.4 | AC3: 2.1 | AD3: 20.2 | AG3: Austin Reaves | AH3: 0.46 | AI3: 0.377 | AJ3: 4.5 | AK3: 5.8 | AL3: 0.7 | AM3: 20.2
A4: 3 | B4: LeBron James | C4: 40 | D4: SF | E4: 70 | F4: 70 | G4: 34.9 | H4: 9.3 | I4: 18.1 | J4: 0.513 | K4: 2.1 | L4: 5.7 | M4: 0.376 | N4: 7.2 | O4: 12.5 | P4: 0.574 | Q4: 0.571 | R4: 3.7 | S4: 4.7 | T4: 0.782 | U4: 1 | V4: 6.8 | W4: 7.8 | X4: 8.2 | Y4: 1 | Z4: 0.6 | AA4: =SUM(Worksheet[[#This Row],[STL]:[BLK]])/2 -> 0.8 | AB4: 3.7 | AC4: 1.4 | AD4: 24.4 | AE4: MVP-6,CPOY-7,AS,NBA2 | AG4: LeBron James | AH4: 0.513 | AI4: 0.376 | AJ4: 7.8 | AK4: 8.2 | AL4: 0.8 | AM4: 24.4 | AN4: MVP-6,CPOY-7,AS,NBA2
A5: 4 | B5: Anthony Davis | C5: 31 | D5: C | E5: 42 | F5: 42 | G5: 34.3 | H5: 9.5 | I5: 18 | J5: 0.528 | K5: 0.7 | L5: 2.2 | M5: 0.298 | N5: 8.9 | O5: 15.8 | P5: 0.56 | Q5: 0.546 | R5: 6 | S5: 7.6 | T5: 0.788 | U5: 2.8 | V5: 9 | W5: 11.9 | X5: 3.4 | Y5: 1.3 | Z5: 2.1 | AA5: =SUM(Worksheet[[#This Row],[STL]:[BLK]])/2 -> 1.7 | AB5: 2.2 | AC5: 2 | AD5: 25.7 | AE5: AS | AG5: Anthony Davis | AH5: 0.528 | AI5: 0.298 | AJ5: 11.9 | AK5: 3.4 | AL5: 1.7 | AM5: 25.7 | AN5: AS
A6: 5 | B6: Rui Hachimura | C6: 26 | D6: PF | E6: 59 | F6: 57 | G6: 31.7 | H6: 5 | I6: 9.8 | J6: 0.509 | K6: 1.7 | L6: 4.2 | M6: 0.413 | N6: 3.2 | O6: 5.6 | P6: 0.581 | Q6: 0.597 | R6: 1.5 | S6: 1.9 | T6: 0.77 | U6: 1.3 | V6: 3.7 | W6: 5 | X6: 1.4 | Y6: 0.8 | Z6: 0.4 | AA6: =SUM(Worksheet[[#This Row],[STL]:[BLK]])/2 -> 0.6 | AB6: 0.8 | AC6: 1.8 | AD6: 13.1 | AG6: Rui Hachimura | AH6: 0.509 | AI6: 0.413 | AJ6: 5 | AK6: 1.4 | AL6: 0.6 | AM6: 13.1
A7: 6 | B7: Dorian Finney-Smith | C7: 31 | D7: PF | E7: 43 | F7: 20 | G7: 28.8 | H7: 2.8 | I7: 6.4 | J7: 0.442 | K7: 1.9 | L7: 4.8 | M7: 0.398 | N7: 0.9 | O7: 1.6 | P7: 0.571 | Q7: 0.591 | R7: 0.3 | S7: 0.5 | T7: 0.714 | U7: 1.1 | V7: 2.5 | W7: 3.6 | X7: 1.4 | Y7: 0.9 | Z7: 0.3 | AA7: =SUM(Worksheet[[#This Row],[STL]:[BLK]])/2 -> 0.6 | AB7: 0.9 | AC7: 1.9 | AD7: 7.9 | AG7: Dorian Finney-Smith | AH7: 0.442 | AI7: 0.398 | AJ7: 3.6 | AK7: 1.4 | AL7: 0.6 | AM7: 7.9
A8: 7 | B8: D'Angelo Russell | C8: 28 | D8: PG | E8: 29 | F8: 10 | G8: 26.3 | H8: 4.4 | I8: 10.7 | J8: 0.415 | K8: 1.9 | L8: 5.8 | M8: 0.333 | N8: 2.5 | O8: 4.9 | P8: 0.51 | Q8: 0.505 | R8: 1.6 | S8: 1.8 | T8: 0.849 | U8: 0.3 | V8: 2.5 | W8: 2.8 | X8: 4.7 | Y8: 0.8 | Z8: 0.1 | AA8: =SUM(Worksheet[[#This Row],[STL]:[BLK]])/2 -> 0.45 | AB8: 1.7 | AC8: 1.8 | AD8: 12.4 | AG8: D'Angelo Russell | AH8: 0.415 | AI8: 0.333 | AJ8: 2.8 | AK8: 4.7 | AL8: 0.45 | AM8: 12.4
A9: 8 | B9: Max Christie | C9: 21 | D9: SG | E9: 46 | F9: 25 | G9: 25.1 | H9: 2.8 | I9: 6.3 | J9: 0.444 | K9: 1.3 | L9: 3.5 | M9: 0.368 | N9: 1.5 | O9: 2.7 | P9: 0.544 | Q9: 0.549 | R9: 1.6 | S9: 1.9 | T9: 0.851 | U9: 0.5 | V9: 2.1 | W9: 2.7 | X9: 1.4 | Y9: 0.8 | Z9: 0.5 | AA9: =SUM(Worksheet[[#This Row],[STL]:[BLK]])/2 -> 0.65 | AB9: 0.8 | AC9: 1.6 | AD9: 8.5 | AG9: Max Christie | AH9: 0.444 | AI9: 0.368 | AJ9: 2.7 | AK9: 1.4 | AL9: 0.65 | AM9: 8.5
A10: 9 | B10: Gabe Vincent | C10: 28 | D10: PG | E10: 72 | F10: 11 | G10: 21.2 | H10: 2.3 | I10: 5.8 | J10: 0.4 | K10: 1.5 | L10: 4.3 | M10: 0.353 | N10: 0.8 | O10: 1.5 | P10: 0.532 | Q10: 0.53 | R10: 0.2 | S10: 0.3 | T10: 0.714 | U10: 0.3 | V10: 1 | W10: 1.3 | X10: 1.4 | Y10: 0.7 | Z10: 0.2 | AA10: =SUM(Worksheet[[#This Row],[STL]:[BLK]])/2 -> 0.45 | AB10: 0.6 | AC10: 2.1 | AD10: 6.4 | AG10: Gabe Vincent | AH10: 0.4 | AI10: 0.353 | AJ10: 1.3 | AK10: 1.4 | AL10: 0.45 | AM10: 6.4
A11: 10 | B11: Jaxson Hayes | C11: 24 | D11: C | E11: 56 | F11: 35 | G11: 19.5 | H11: 2.9 | I11: 4 | J11: 0.722 | K11: 0 | L11: 0.1 | M11: 0 | N11: 2.9 | O11: 3.9 | P11: 0.732 | Q11: 0.722 | R11: 1.1 | S11: 1.8 | T11: 0.622 | U11: 1.4 | V11: 3.4 | W11: 4.8 | X11: 1 | Y11: 0.6 | Z11: 0.9 | AA11: =SUM(Worksheet[[#This Row],[STL]:[BLK]])/2 -> 0.75 | AB11: 0.8 | AC11: 2.4 | AD11: 6.8 | AG11: Jaxson Hayes | AH11: 0.722 | AI11: 0 | AJ11: 4.8 | AK11: 1 | AL11: 0.75 | AM11: 6.8
A12: 11 | B12: Dalton Knecht | C12: 23 | D12: SF | E12: 78 | F12: 16 | G12: 19.2 | H12: 3.3 | I12: 7.1 | J12: 0.461 | K12: 1.6 | L12: 4.4 | M12: 0.376 | N12: 1.7 | O12: 2.8 | P12: 0.594 | Q12: 0.576 | R12: 0.8 | S12: 1.1 | T12: 0.762 | U12: 0.5 | V12: 2.3 | W12: 2.8 | X12: 0.8 | Y12: 0.3 | Z12: 0.1 | AA12: =SUM(Worksheet[[#This Row],[STL]:[BLK]])/2 -> 0.2 | AB12: 0.5 | AC12: 1.2 | AD12: 9.1 | AG12: Dalton Knecht | AH12: 0.461 | AI12: 0.376 | AJ12: 2.8 | AK12: 0.8 | AL12: 0.2 | AM12: 9.1
A13: 12 | B13: Jordan Goodwin | C13: 26 | D13: PG | E13: 29 | F13: 5 | G13: 18.7 | H13: 2.2 | I13: 5 | J13: 0.438 | K13: 0.9 | L13: 2.3 | M13: 0.382 | N13: 1.3 | O13: 2.6 | P13: 0.487 | Q13: 0.528 | R13: 0.3 | S13: 0.4 | T13: 0.818 | U13: 1.3 | V13: 2.6 | W13: 3.9 | X13: 1.4 | Y13: 1 | Z13: 0.4 | AA13: =SUM(Worksheet[[#This Row],[STL]:[BLK]])/2 -> 0.7 | AB13: 0.9 | AC13: 1.5 | AD13: 5.6 | AG13: Jordan Goodwin | AH13: 0.438 | AI13: 0.382 | AJ13: 3.9 | AK13: 1.4 | AL13: 0.7 | AM13: 5.6
A14: 13 | B14: Cam Reddish | C14: 25 | D14: SF | E14: 33 | F14: 8 | G14: 17.8 | H14: 1.2 | I14: 2.8 | J14: 0.404 | K14: 0.4 | L14: 1.4 | M14: 0.277 | N14: 0.8 | O14: 1.4 | P14: 0.532 | Q14: 0.473 | R14: 0.5 | S14: 0.8 | T14: 0.615 | U14: 0.5 | V14: 1.5 | W14: 2 | X14: 0.7 | Y14: 1 | Z14: 0.3 | AA14: =SUM(Worksheet[[#This Row],[STL]:[BLK]])/2 -> 0.65 | AB14: 0.4 | AC14: 1.3 | AD14: 3.2 | AG14: Cam Reddish | AH14: 0.404 | AI14: 0.277 | AJ14: 2 | AK14: 0.7 | AL14: 0.65 | AM14: 3.2
A15: 14 | B15: Jarred Vanderbilt | C15: 25 | D15: PF | E15: 36 | F15: 2 | G15: 16.1 | H15: 1.6 | I15: 3.4 | J15: 0.488 | K15: 0.3 | L15: 0.9 | M15: 0.281 | N15: 1.4 | O15: 2.5 | P15: 0.562 | Q15: 0.525 | R15: 0.6 | S15: 1 | T15: 0.556 | U15: 1.9 | V15: 3.2 | W15: 5.1 | X15: 1.1 | Y15: 1 | Z15: 0.3 | AA15: =SUM(Worksheet[[#This Row],[STL]:[BLK]])/2 -> 0.65 | AB15: 0.8 | AC15: 1.9 | AD15: 4.1 | AG15: Jarred Vanderbilt | AH15: 0.488 | AI15: 0.281 | AJ15: 5.1 | AK15: 1.1 | AL15: 0.65 | AM15: 4.1
A16: 15 | B16: Markieff Morris | C16: 35 | D16: PF | E16: 8 | F16: 2 | G16: 15.5 | H16: 2 | I16: 6 | J16: 0.333 | K16: 0.9 | L16: 2.9 | M16: 0.304 | N16: 1.1 | O16: 3.1 | P16: 0.36 | Q16: 0.406 | R16: 0.6 | S16: 0.8 | T16: 0.833 | U16: 0.4 | V16: 1.5 | W16: 1.9 | X16: 2.1 | Y16: 0.1 | Z16: 0.3 | AA16: =SUM(Worksheet[[#This Row],[STL]:[BLK]])/2 -> 0.2 | AB16: 0.4 | AC16: 1.8 | AD16: 5.5 | AG16: Markieff Morris | AH16: 0.333 | AI16: 0.304 | AJ16: 1.9 | AK16: 2.1 | AL16: 0.2 | AM16: 5.5
A17: 16 | B17: Alex Len | C17: 31 | D17: C | E17: 10 | F17: 4 | G17: 12.2 | H17: 1 | I17: 2.2 | J17: 0.455 | K17: 0.1 | L17: 0.3 | M17: 0.333 | N17: 0.9 | O17: 1.9 | P17: 0.474 | Q17: 0.477 | R17: 0.1 | S17: 0.4 | T17: 0.25 | U17: 1.3 | V17: 1.8 | W17: 3.1 | X17: 0.8 | Y17: 0.1 | Z17: 0.3 | AA17: =SUM(Worksheet[[#This Row],[STL]:[BLK]])/2 -> 0.2 | AB17: 0.9 | AC17: 2.1 | AD17: 2.2 | AG17: Alex Len | AH17: 0.455 | AI17: 0.333 | AJ17: 3.1 | AK17: 0.8 | AL17: 0.2 | AM17: 2.2
A18: 17 | B18: Shake Milton | C18: 28 | D18: SG | E18: 30 | F18: 1 | G18: 11.5 | H18: 1.4 | I18: 3.2 | J18: 0.433 | K18: 0.3 | L18: 1.1 | M18: 0.294 | N18: 1.1 | O18: 2.1 | P18: 0.508 | Q18: 0.485 | R18: 0.7 | S18: 0.9 | T18: 0.846 | U18: 0.5 | V18: 1.3 | W18: 1.8 | X18: 1.3 | Y18: 0.3 | Z18: 0.1 | AA18: =SUM(Worksheet[[#This Row],[STL]:[BLK]])/2 -> 0.2 | AB18: 0.7 | AC18: 0.8 | AD18: 3.9 | AG18: Shake Milton | AH18: 0.433 | AI18: 0.294 | AJ18: 1.8 | AK18: 1.3 | AL18: 0.2 | AM18: 3.9
A19: 18 | B19: Trey Jemison | C19: 25 | D19: C | E19: 22 | F19: 0 | G19: 10.3 | H19: 1.2 | I19: 1.9 | J19: 0.619 | K19: 0 | L19: 0 | N19: 1.2 | O19: 1.9 | P19: 0.619 | Q19: 0.619 | R19: 0.2 | S19: 0.5 | T19: 0.417 | U19: 1 | V19: 1.8 | W19: 2.8 | X19: 0.3 | Y19: 0.1 | Z19: 0.4 | AA19: =SUM(Worksheet[[#This Row],[STL]:[BLK]])/2 -> 0.25 | AB19: 0.6 | AC19: 1.9 | AD19: 2.6 | AG19: Trey Jemison | AH19: 0.619 | AJ19: 2.8 | AK19: 0.3 | AL19: 0.25 | AM19: 2.6
A20: 19 | B20: Christian Koloko | C20: 24 | D20: C | E20: 37 | F20: 0 | G20: 9.2 | H20: 1.1 | I20: 1.8 | J20: 0.606 | K20: 0 | L20: 0.1 | M20: 0 | N20: 1.1 | O20: 1.7 | P20: 0.645 | Q20: 0.606 | R20: 0.3 | S20: 0.4 | T20: 0.714 | U20: 0.9 | V20: 1.5 | W20: 2.5 | X20: 0.4 | Y20: 0.2 | Z20: 0.4 | AA20: =SUM(Worksheet[[#This Row],[STL]:[BLK]])/2 -> 0.3 | AB20: 0.3 | AC20: 1.2 | AD20: 2.4 | AG20: Christian Koloko | AH20: 0.606 | AI20: 0 | AJ20: 2.5 | AK20: 0.4 | AL20: 0.3 | AM20: 2.4
A21: 20 | B21: Armel Traoré | C21: 22 | D21: SF | E21: 9 | F21: 0 | G21: 7.4 | H21: 0.7 | I21: 2.1 | J21: 0.316 | K21: 0 | L21: 0.8 | M21: 0 | N21: 0.7 | O21: 1.3 | P21: 0.5 | Q21: 0.316 | R21: 0.2 | S21: 0.8 | T21: 0.286 | U21: 0.2 | V21: 1.4 | W21: 1.7 | X21: 0.1 | Y21: 0.4 | Z21: 0.2 | AA21: =SUM(Worksheet[[#This Row],[STL]:[BLK]])/2 -> 0.3 | AB21: 0.3 | AC21: 0.7 | AD21: 1.6 | AG21: Armel Traoré | AH21: 0.316 | AI21: 0 | AJ21: 1.7 | AK21: 0.1 | AL21: 0.3 | AM21: 1.6
A22: 21 | B22: Jalen Hood-Schifino | C22: 21 | D22: SG | E22: 2 | F22: 0 | G22: 7 | H22: 0.5 | I22: 0.5 | J22: 1 | K22: 0 | L22: 0 | N22: 0.5 | O22: 0.5 | P22: 1 | Q22: 1 | R22: 1 | S22: 1 | T22: 1 | U22: 0.5 | V22: 0 | W22: 0.5 | X22: 0.5 | Y22: 0 | Z22: 0.5 | AA22: =SUM(Worksheet[[#This Row],[STL]:[BLK]])/2 -> 0.25 | AB22: 0.5 | AC22: 1.5 | AD22: 2 | AG22: Jalen Hood-Schifino | AH22: 1 | AJ22: 0.5 | AK22: 0.5 | AL22: 0.25 | AM22: 2
A23: 22 | B23: Bronny James | C23: 20 | D23: SG | E23: 27 | F23: 1 | G23: 6.7 | H23: 0.8 | I23: 2.5 | J23: 0.313 | K23: 0.3 | L23: 1.2 | M23: 0.281 | N23: 0.4 | O23: 1.3 | P23: 0.343 | Q23: 0.381 | R23: 0.4 | S23: 0.5 | T23: 0.786 | U23: 0.1 | V23: 0.5 | W23: 0.7 | X23: 0.8 | Y23: 0.3 | Z23: 0.1 | AA23: =SUM(Worksheet[[#This Row],[STL]:[BLK]])/2 -> 0.2 | AB23: 0.5 | AC23: 0.5 | AD23: 2.3 | AG23: Bronny James | AH23: 0.313 | AI23: 0.281 | AJ23: 0.7 | AK23: 0.8 | AL23: 0.2 | AM23: 2.3
A24: 23 | B24: Quincy Olivari | C24: 23 | D24: PG | E24: 2 | F24: 0 | G24: 5 | H24: 0.5 | I24: 2.5 | J24: 0.2 | K24: 0.5 | L24: 2.5 | M24: 0.2 | N24: 0 | O24: 0 | Q24: 0.3 | R24: 0 | S24: 0 | U24: 0 | V24: 0 | W24: 0 | X24: 0.5 | Y24: 0 | Z24: 0 | AA24: =SUM(Worksheet[[#This Row],[STL]:[BLK]])/2 -> 0 | AB24: 0.5 | AC24: 0 | AD24: 1.5 | AG24: Quincy Olivari | AH24: 0.2 | AI24: 0.2 | AJ24: 0 | AK24: 0.5 | AL24: 0 | AM24: 1.5
A25: 24 | B25: Maxwell Lewis | C25: 22 | D25: SF | E25: 7 | F25: 0 | G25: 4.1 | H25: 0.3 | I25: 0.9 | J25: 0.333 | K25: 0 | L25: 0 | N25: 0.3 | O25: 0.9 | P25: 0.333 | Q25: 0.333 | R25: 0 | S25: 0 | U25: 0.3 | V25: 0 | W25: 0.3 | X25: 0.3 | Y25: 0.1 | Z25: 0 | AA25: =SUM(Worksheet[[#This Row],[STL]:[BLK]])/2 -> 0.05 | AB25: 0.3 | AC25: 0.1 | AD25: 0.6 | AG25: Maxwell Lewis | AH25: 0.333 | AJ25: 0.3 | AK25: 0.3 | AL25: 0.05 | AM25: 0.6

Sheet Luka_24_25_Regular_Playoffs
A1: Rk | B1: Gtm | C1: Date | D1: Season Type | E1: Team | F1: @ | G1: Opp | H1: W/L | I1: SCORE | J1: GS | K1: MP | L1: FG | M1: FGA | N1: FG% | O1: 3P | P1: 3PA | Q1: 3P% | R1: 2P | S1: 2PA | T1: 2P% | U1: eFG% | V1: FT | W1: FTA | X1: FT% | Y1: ORB | Z1: DRB | AA1: TRB | AB1: AST | AC1: STL | AD1: BLK | AE1: TOV | AF1: PF | AG1: PTS | AH1: GmSc | AI1: +/-
A2: 1 | B2: 1 | C2: 45589 | D2: REGULAR | E2: DAL | G2: SAS | H2: W | I2: 120-109 | J2: * | K2: 36.266667 | L2: 9 | M2: 25 | N2: 0.36 | O2: 4 | P2: 11 | Q2: 0.364 | R2: 5 | S2: 14 | T2: 0.357 | U2: 0.44 | V2: 6 | W2: 8 | X2: 0.75 | Y2: 1 | Z2: 9 | AA2: 10 | AB2: 8 | AC2: 1 | AD2: 1 | AE2: 4 | AF2: 3 | AG2: 28 | AH2: 18.8 | AI2: 6
A3: 2 | B3: 2 | C3: 45591 | D3: REGULAR | E3: DAL | F3: @ | G3: PHO | H3: L | I3: 102-114 | J3: * | K3: 39.4 | L3: 12 | M3: 25 | N3: 0.48 | O3: 5 | P3: 13 | Q3: 0.385 | R3: 7 | S3: 12 | T3: 0.583 | U3: 0.58 | V3: 11 | W3: 12 | X3: 0.917 | Y3: 1 | Z3: 9 | AA3: 10 | AB3: 4 | AC3: 0 | AD3: 1 | AE3: 2 | AF3: 4 | AG3: 40 | AH3: 30.2 | AI3: -12
A4: 3 | B4: 3 | C4: 45593 | D4: REGULAR | E4: DAL | G4: UTA | H4: W | I4: 110-102 | J4: * | K4: 33.2 | L4: 5 | M4: 22 | N4: 0.227 | O4: 1 | P4: 9 | Q4: 0.111 | R4: 4 | S4: 13 | T4: 0.308 | U4: 0.25 | V4: 4 | W4: 6 | X4: 0.667 | Y4: 0 | Z4: 9 | AA4: 9 | AB4: 8 | AC4: 2 | AD4: 1 | AE4: 2 | AF4: 5 | AG4: 15 | AH4: 7.8 | AI4: 5
A5: 4 | B5: 4 | C5: 45594 | D5: REGULAR | E5: DAL | F5: @ | G5: MIN | H5: W | I5: 120-114 | J5: * | K5: 40.15 | L5: 10 | M5: 27 | N5: 0.37 | O5: 1 | P5: 8 | Q5: 0.125 | R5: 9 | S5: 19 | T5: 0.474 | U5: 0.389 | V5: 3 | W5: 4 | X5: 0.75 | Y5: 1 | Z5: 7 | AA5: 8 | AB5: 8 | AC5: 1 | AD5: 0 | AE5: 3 | AF5: 2 | AG5: 24 | AH5: 14.3 | AI5: 3
A6: 5 | B6: 5 | C6: 45596 | D6: REGULAR | E6: DAL | G6: HOU | H6: L | I6: 102-108 | J6: * | K6: 37.516667 | L6: 12 | M6: 25 | N6: 0.48 | O6: 3 | P6: 7 | Q6: 0.429 | R6: 9 | S6: 18 | T6: 0.5 | U6: 0.54 | V6: 2 | W6: 4 | X6: 0.5 | Y6: 0 | Z6: 5 | AA6: 5 | AB6: 2 | AC6: 1 | AD6: 0 | AE6: 1 | AF6: 5 | AG6: 29 | AH6: 16.4 | AI6: -2
A7: 6 | B7: 6 | C7: 45599 | D7: REGULAR | E7: DAL | G7: ORL | H7: W | I7: 108-85 | J7: * | K7: 31.716667 | L7: 11 | M7: 22 | N7: 0.5 | O7: 5 | P7: 13 | Q7: 0.385 | R7: 6 | S7: 9 | T7: 0.667 | U7: 0.614 | V7: 5 | W7: 7 | X7: 0.714 | Y7: 1 | Z7: 8 | AA7: 9 | AB7: 7 | AC7: 0 | AD7: 0 | AE7: 4 | AF7: 3 | AG7: 32 | AH7: 23 | AI7: 21
A8: 7 | B8: 7 | C8: 45600 | D8: REGULAR | E8: DAL | G8: IND | H8: L | I8: 127-134 | J8: * | K8: 42.35 | L8: 9 | M8: 24 | N8: 0.375 | O8: 4 | P8: 10 | Q8: 0.4 | R8: 5 | S8: 14 | T8: 0.357 | U8: 0.458 | V8: 12 | W8: 15 | X8: 0.8 | Y8: 0 | Z8: 7 | AA8: 7 | AB8: 15 | AC8: 2 | AD8: 0 | AE8: 2 | AF8: 3 | AG8: 34 | AH8: 31 | AI8: -3
A9: 8 | B9: 8 | C9: 45602 | D9: REGULAR | E9: DAL | G9: CHI | H9: W | I9: 119-99 | J9: * | K9: 32.316667 | L9: 8 | M9: 19 | N9: 0.421 | O9: 3 | P9: 8 | Q9: 0.375 | R9: 5 | S9: 11 | T9: 0.455 | U9: 0.5 | V9: 8 | W9: 9 | X9: 0.889 | Y9: 0 | Z9: 7 | AA9: 7 | AB9: 13 | AC9: 4 | AD9: 0 | AE9: 5 | AF9: 3 | AG9: 27 | AH9: 25.5 | AI9: 35
A10: 9 | B10: 9 | C10: 45604 | D10: REGULAR | E10: DAL | G10: PHO | H10: L | I10: 113-114 | J10: * | K10: 42.183333 | L10: 11 | M10: 25 | N10: 0.44 | O10: 5 | P10: 12 | Q10: 0.417 | R10: 6 | S10: 13 | T10: 0.462 | U10: 0.54 | V10: 3 | W10: 3 | X10: 1 | Y10: 0 | Z10: 7 | AA10: 7 | AB10: 7 | AC10: 1 | AD10: 0 | AE10: 3 | AF10: 3 | AG10: 30 | AH10: 20.7 | AI10: -4
A11: 10 | B11: 10 | C11: 45606 | D11: REGULAR | E11: DAL | F11: @ | G11: DEN | H11: L | I11: 120-122 | J11: * | K11: 40.85 | L11: 9 | M11: 19 | N11: 0.474 | O11: 2 | P11: 8 | Q11: 0.25 | R11: 7 | S11: 11 | T11: 0.636 | U11: 0.526 | V11: 4 | W11: 6 | X11: 0.667 | Y11: 1 | Z11: 8 | AA11: 9 | AB11: 9 | AC11: 1 | AD11: 1 | AE11: 5 | AF11: 2 | AG11: 24 | AH11: 18.8 | AI11: 5
A12: 11 | B12: 11 | C12: 45608 | D12: REGULAR | E12: DAL | F12: @ | G12: GSW | H12: L | I12: 117-120 | J12: * | K12: 41.083333 | L12: 13 | M12: 27 | N12: 0.481 | O12: 2 | P12: 10 | Q12: 0.2 | R12: 11 | S12: 17 | T12: 0.647 | U12: 0.519 | V12: 3 | W12: 3 | X12: 1 | Y12: 0 | Z12: 8 | AA12: 8 | AB12: 6 | AC12: 3 | AD12: 0 | AE12: 5 | AF12: 2 | AG12: 31 | AH12: 21.1 | AI12: 2
A13: 12 | B13: 12 | C13: 45610 | D13: REGULAR | E13: DAL | F13: @ | G13: UTA | H13: L | I13: 113-115 | J13: * | K13: 38.066667 | L13: 13 | M13: 25 | N13: 0.52 | O13: 4 | P13: 13 | Q13: 0.308 | R13: 9 | S13: 12 | T13: 0.75 | U13: 0.6 | V13: 7 | W13: 7 | X13: 1 | Y13: 1 | Z13: 6 | AA13: 7 | AB13: 9 | AC13: 1 | AD13: 0 | AE13: 3 | AF13: 0 | AG13: 37 | AH13: 31.5 | AI13: -8
A14: 13 | B14: 13 | C14: 45612 | D14: REGULAR | E14: DAL | G14: SAS | H14: W | I14: 110-93 | J14: * | K14: 28.4 | L14: 6 | M14: 16 | N14: 0.375 | O14: 3 | P14: 9 | Q14: 0.333 | R14: 3 | S14: 7 | T14: 0.429 | U14: 0.469 | V14: 1 | W14: 3 | X14: 0.333 | Y14: 2 | Z14: 4 | AA14: 6 | AB14: 6 | AC14: 2 | AD14: 0 | AE14: 4 | AF14: 4 | AG14: 16 | AH14: 9.6 | AI14: 15
A15: 13 | B15: 14 | C15: 45613 | D15: REGULAR | E15: DAL | F15: @ | G15: OKC | H15: W | I15: 121-119 | J15: Inactive | K15: 0
A16: 14 | B16: 15 | C16: 45615 | D16: REGULAR | E16: DAL | G16: NOP | H16: W | I16: 132-91 | J16: * | K16: 29.616667 | L16: 10 | M16: 16 | N16: 0.625 | O16: 3 | P16: 8 | Q16: 0.375 | R16: 7 | S16: 8 | T16: 0.875 | U16: 0.719 | V16: 3 | W16: 5 | X16: 0.6 | Y16: 0 | Z16: 5 | AA16: 5 | AB16: 5 | AC16: 3 | AD16: 1 | AE16: 3 | AF16: 0 | AG16: 26 | AH16: 23.7 | AI16: 28
A17: 14 | B17: 16 | C17: 45618 | D17: REGULAR | E17: DAL | F17: @ | G17: DEN | H17: W | I17: 123-120 | J17: Inactive | K17: 0
A18: 14 | B18: 17 | C18: 45620 | D18: REGULAR | E18: DAL | F18: @ | G18: MIA | H18: L | I18: 118-123 (OT) | J18: Inactive | K18: 0
A19: 14 | B19: 18 | C19: 45621 | D19: REGULAR | E19: DAL | F19: @ | G19: ATL | H19: W | I19: 129-119 | J19: Inactive | K19: 0
A20: 14 | B20: 19 | C20: 45623 | D20: REGULAR | E20: DAL | G20: NYK | H20: W | I20: 129-114 | J20: Inactive | K20: 0
A21: 14 | B21: 20 | C21: 45626 | D21: REGULAR | E21: DAL | F21: @ | G21: UTA | H21: W | I21: 106-94 | J21: Inactive | K21: 0
A22: 15 | B22: 21 | C22: 45627 | D22: REGULAR | E22: DAL | F22: @ | G22: POR | H22: W | I22: 137-131 | J22: * | K22: 36.283333 | L22: 15 | M22: 24 | N22: 0.625 | O22: 4 | P22: 10 | Q22: 0.4 | R22: 11 | S22: 14 | T22: 0.786 | U22: 0.708 | V22: 2 | W22: 4 | X22: 0.5 | Y22: 0 | Z22: 7 | AA22: 7 | AB22: 13 | AC22: 3 | AD22: 0 | AE22: 3 | AF22: 2 | AG22: 36 | AH22: 34.8 | AI22: 1
A23: 16 | B23: 22 | C23: 45629 | D23: REGULAR | E23: DAL | G23: MEM | H23: W | I23: 121-116 | J23: * | K23: 40.466667 | L23: 11 | M23: 22 | N23: 0.5 | O23: 5 | P23: 9 | Q23: 0.556 | R23: 6 | S23: 13 | T23: 0.462 | U23: 0.614 | V23: 10 | W23: 16 | X23: 0.625 | Y23: 3 | Z23: 9 | AA23: 12 | AB23: 4 | AC23: 4 | AD23: 1 | AE23: 3 | AF23: 4 | AG23: 37 | AH23: 31.3 | AI23: 16
A24: 17 | B24: 23 | C24: 45631 | D24: REGULAR | E24: DAL | F24: @ | G24: WAS | H24: W | I24: 137-101 | J24: * | K24: 32.4 | L24: 7 | M24: 17 | N24: 0.412 | O24: 3 | P24: 10 | Q24: 0.3 | R24: 4 | S24: 7 | T24: 0.571 | U24: 0.5 | V24: 4 | W24: 5 | X24: 0.8 | Y24: 0 | Z24: 10 | AA24: 10 | AB24: 10 | AC24: 2 | AD24: 1 | AE24: 4 | AF24: 2 | AG24: 21 | AH24: 19.4 | AI24: 36
A25: 18 | B25: 24 | C25: 45633 | D25: REGULAR | E25: DAL | F25: @ | G25: TOR | H25: W | I25: 125-118 | J25: * | K25: 38.233333 | L25: 9 | M25: 20 | N25: 0.45 | O25: 6 | P25: 13 | Q25: 0.462 | R25: 3 | S25: 7 | T25: 0.429 | U25: 0.6 | V25: 6 | W25: 6 | X25: 1 | Y25: 0 | Z25: 13 | AA25: 13 | AB25: 11 | AC25: 4 | AD25: 0 | AE25: 4 | AF25: 4 | AG25: 30 | AH25: 29.6 | AI25: 10
A26: 19 | B26: 25 | C26: 45636 | D26: REGULAR | E26: DAL | F26: @ | G26: OKC | H26: L | I26: 104-118 | J26: * | K26: 40.166667 | L26: 5 | M26: 15 | N26: 0.333 | O26: 2 | P26: 8 | Q26: 0.25 | R26: 3 | S26: 7 | T26: 0.429 | U26: 0.4 | V26: 4 | W26: 5 | X26: 0.8 | Y26: 1 | Z26: 10 | AA26: 11 | AB26: 5 | AC26: 4 | AD26: 0 | AE26: 6 | AF26: 3 | AG26: 16 | AH26: 11.1 | AI26: -14
A27: 20 | B27: 26 | C27: 45641 | D27: REGULAR | E27: DAL | F27: @ | G27: GSW | H27: W | I27: 143-133 | J27: * | K27: 37.85 | L27: 16 | M27: 23 | N27: 0.696 | O27: 6 | P27: 11 | Q27: 0.545 | R27: 10 | S27: 12 | T27: 0.833 | U27: 0.826 | V27: 7 | W27: 9 | X27: 0.778 | Y27: 2 | Z27: 9 | AA27: 11 | AB27: 13 | AC27: 3 | AD27: 2 | AE27: 3 | AF27: 1 | AG27: 45 | AH27: 48.7 | AI27: 18
A28: 20 | B28: 27 | C28: 45645 | D28: REGULAR | E28: DAL | G28: LAC | H28: L | I28: 95-118 | J28: Inactive | K28: 0
A29: 20 | B29: 28 | C29: 45647 | D29: REGULAR | E29: DAL | G29: LAC | H29: W | I29: 113-97 | J29: Inactive | K29: 0
A30: 21 | B30: 29 | C30: 45649 | D30: REGULAR | E30: DAL | G30: POR | H30: W | I30: 132-108 | J30: * | K30: 29.783333 | L30: 10 | M30: 19 | N30: 0.526 | O30: 1 | P30: 7 | Q30: 0.143 | R30: 9 | S30: 12 | T30: 0.75 | U30: 0.553 | V30: 6 | W30: 8 | X30: 0.75 | Y30: 1 | Z30: 6 | AA30: 7 | AB30: 7 | AC30: 1 | AD30: 0 | AE30: 3 | AF30: 2 | AG30: 27 | AH30: 21.5 | AI30: 16
A31: 22 | B31: 30 | C31: 45651 | D31: REGULAR | E31: DAL | G31: MIN | H31: L | I31: 99-105 | J31: * | K31: 16.216667 | L31: 5 | M31: 9 | N31: 0.556 | O31: 3 | P31: 5 | Q31: 0.6 | R31: 2 | S31: 4 | T31: 0.5 | U31: 0.722 | V31: 1 | W31: 1 | X31: 1 | Y31: 1 | Z31: 4 | AA31: 5 | AB31: 2 | AC31: 1 | AD31: 0 | AE31: 3 | AF31: 1 | AG31: 14 | AH31: 10.6 | AI31: -6
A32: 22 | B32: 31 | C32: 45653 | D32: REGULAR | E32: DAL | F32: @ | G32: PHO | H32: W | I32: 98-89 | J32: Inactive | K32: 0
A33: 22 | B33: 32 | C33: 45654 | D33: REGULAR | E33: DAL | F33: @ | G33: POR | H33: L | I33: 122-126 | J33: Inactive | K33: 0
A34: 22 | B34: 33 | C34: 45656 | D34: REGULAR | E34: DAL | F34: @ | G34: SAC | H34: L | I34: 100-110 | J34: Inactive | K34: 0
A35: 22 | B35: 34 | C35: 45658 | D35: REGULAR | E35: DAL | F35: @ | G35: HOU | H35: L | I35: 99-110 | J35: Inactive | K35: 0
A36: 22 | B36: 35 | C36: 45660 | D36: REGULAR | E36: DAL | G36: CLE | H36: L | I36: 122-134 | J36: Inactive | K36: 0
A37: 22 | B37: 36 | C37: 45663 | D37: REGULAR | E37: DAL | F37: @ | G37: MEM | H37: L | I37: 104-119 | J37: Inactive | K37: 0
A38: 22 | B38: 37 | C38: 45664 | D38: REGULAR | E38: DAL | G38: LAL | H38: W | I38: 118-97 | J38: Inactive | K38: 0
A39: 22 | B39: 38 | C39: 45666 | D39: REGULAR | E39: DAL | G39: POR | H39: W | I39: 117-111 | J39: Inactive | K39: 0
A40: 22 | B40: 39 | C40: 45669 | D40: REGULAR | E40: DAL | G40: DEN | H40: L | I40: 101-112 | J40: Inactive | K40: 0
...

Sheet Lebron_regular_Playoffs
A1: Rk | B1: Gtm | C1: Date | D1: Column1 | E1: Season Type | F1: Team | G1: @ | H1: Opp | I1: W/L | J1: Result.2 | K1: GS | L1: MP | M1: FG | N1: FGA | O1: FG% | P1: 3P | Q1: 3PA | R1: 3P% | S1: 2P | T1: 2PA | U1: 2P% | V1: eFG% | W1: FT | X1: FTA | Y1: FT% | Z1: ORB | AA1: DRB | AB1: TRB | AC1: AST | AD1: STL | AE1: BLK | AF1: TOV | AG1: PF | AH1: PTS | AI1: GmSc | AJ1: +/-
A2: 1 | B2: 1 | C2: 45587 | D2: No Luka | E2: Regular | F2: LAL | H2: MIN | I2: W | J2: 110-103 | K2: * | L2: 34.65 | M2: 7 | N2: 16 | O2: 0.438 | P2: 1 | Q2: 4 | R2: 0.25 | S2: 6 | T2: 12 | U2: 0.5 | V2: 0.469 | W2: 1 | X2: 1 | Y2: 1 | Z2: 0 | AA2: 5 | AB2: 5 | AC2: 4 | AD2: 0 | AE2: 2 | AF2: 2 | AG2: 3 | AH2: 16 | AI2: 10.1 | AJ2: -6
A3: 2 | B3: 2 | C3: 45590 | D3: No Luka | E3: Regular | F3: LAL | H3: PHO | I3: W | J3: 123-116 | K3: * | L3: 34.7 | M3: 7 | N3: 13 | O3: 0.538 | P3: 2 | Q3: 5 | R3: 0.4 | S3: 5 | T3: 8 | U3: 0.625 | V3: 0.615 | W3: 5 | X3: 8 | Y3: 0.625 | Z3: 0 | AA3: 4 | AB3: 4 | AC3: 8 | AD3: 0 | AE3: 0 | AF3: 2 | AG3: 1 | AH3: 21 | AI3: 17.9 | AJ3: 14
A4: 3 | B4: 3 | C4: 45591 | D4: No Luka | E4: Regular | F4: LAL | H4: SAC | I4: W | J4: 131-127 | K4: * | L4: 33.766667 | M4: 12 | N4: 22 | O4: 0.545 | P4: 4 | Q4: 9 | R4: 0.444 | S4: 8 | T4: 13 | U4: 0.615 | V4: 0.636 | W4: 4 | X4: 4 | Y4: 1 | Z4: 0 | AA4: 14 | AB4: 14 | AC4: 10 | AD4: 0 | AE4: 1 | AF4: 5 | AG4: 3 | AH4: 32 | AI4: 27.1 | AJ4: 13
A5: 4 | B5: 4 | C5: 45593 | D5: No Luka | E5: Regular | F5: LAL | G5: @ | H5: PHO | I5: L | J5: 105-109 | K5: * | L5: 35.8 | M5: 3 | N5: 14 | O5: 0.214 | P5: 2 | Q5: 5 | R5: 0.4 | S5: 1 | T5: 9 | U5: 0.111 | V5: 0.286 | W5: 3 | X5: 6 | Y5: 0.5 | Z5: 0 | AA5: 5 | AB5: 5 | AC5: 8 | AD5: 1 | AE5: 0 | AF5: 2 | AG5: 1 | AH5: 11 | AI5: 6.9 | AJ5: -17
A6: 5 | B6: 5 | C6: 45595 | D6: No Luka | E6: Regular | F6: LAL | G6: @ | H6: CLE | I6: L | J6: 110-134 | K6: * | L6: 28.966667 | M6: 9 | N6: 13 | O6: 0.692 | P6: 1 | Q6: 3 | R6: 0.333 | S6: 8 | T6: 10 | U6: 0.8 | V6: 0.731 | W6: 7 | X6: 7 | Y6: 1 | Z6: 1 | AA6: 5 | AB6: 6 | AC6: 3 | AD6: 0 | AE6: 0 | AF6: 6 | AG6: 2 | AH6: 26 | AI6: 18 | AJ6: -17
A7: 6 | B7: 6 | C7: 45597 | D7: No Luka | E7: Regular | F7: LAL | G7: @ | H7: TOR | I7: W | J7: 131-125 | K7: * | L7: 36.25 | M7: 9 | N7: 17 | O7: 0.529 | P7: 5 | Q7: 8 | R7: 0.625 | S7: 4 | T7: 9 | U7: 0.444 | V7: 0.676 | W7: 4 | X7: 6 | Y7: 0.667 | Z7: 0 | AA7: 6 | AB7: 6 | AC7: 10 | AD7: 1 | AE7: 0 | AF7: 0 | AG7: 1 | AH7: 27 | AI7: 27.3 | AJ7: 11
A8: 7 | B8: 7 | C8: 45600 | D8: No Luka | E8: Regular | F8: LAL | G8: @ | H8: DET | I8: L | J8: 103-115 | K8: * | L8: 40 | M8: 7 | N8: 16 | O8: 0.438 | P8: 1 | Q8: 2 | R8: 0.5 | S8: 6 | T8: 14 | U8: 0.429 | V8: 0.469 | W8: 5 | X8: 5 | Y8: 1 | Z8: 1 | AA8: 7 | AB8: 8 | AC8: 11 | AD8: 2 | AE8: 0 | AF8: 1 | AG8: 1 | AH8: 20 | AI8: 22.7 | AJ8: -16
A9: 8 | B9: 8 | C9: 45602 | D9: No Luka | E9: Regular | F9: LAL | G9: @ | H9: MEM | I9: L | J9: 114-131 | K9: * | L9: 35.416667 | M9: 15 | N9: 24 | O9: 0.625 | P9: 6 | Q9: 11 | R9: 0.545 | S9: 9 | T9: 13 | U9: 0.692 | V9: 0.75 | W9: 3 | X9: 4 | Y9: 0.75 | Z9: 0 | AA9: 7 | AB9: 7 | AC9: 6 | AD9: 1 | AE9: 0 | AF9: 5 | AG9: 2 | AH9: 39 | AI9: 29.3 | AJ9: -21
A10: 9 | B10: 9 | C10: 45604 | D10: No Luka | E10: Regular | F10: LAL | H10: PHI | I10: W | J10: 116-106 | K10: * | L10: 33.8 | M10: 9 | N10: 14 | O10: 0.643 | P10: 2 | Q10: 4 | R10: 0.5 | S10: 7 | T10: 10 | U10: 0.7 | V10: 0.714 | W10: 1 | X10: 1 | Y10: 1 | Z10: 0 | AA10: 12 | AB10: 12 | AC10: 13 | AD10: 0 | AE10: 3 | AF10: 2 | AG10: 0 | AH10: 21 | AI10: 27.6 | AJ10: 12
A11: 10 | B11: 10 | C11: 45606 | D11: No Luka | E11: Regular | F11: LAL | H11: TOR | I11: W | J11: 123-103 | K11: * | L11: 34.783333 | M11: 6 | N11: 14 | O11: 0.429 | P11: 0 | Q11: 3 | R11: 0 | S11: 6 | T11: 11 | U11: 0.545 | V11: 0.429 | W11: 7 | X11: 7 | Y11: 1 | Z11: 2 | AA11: 8 | AB11: 10 | AC11: 16 | AD11: 1 | AE11: 0 | AF11: 3 | AG11: 0 | AH11: 19 | AI11: 24.6 | AJ11: 13
A12: 11 | B12: 11 | C12: 45609 | D12: No Luka | E12: Regular | F12: LAL | H12: MEM | I12: W | J12: 128-123 | K12: * | L12: 36.933333 | M12: 13 | N12: 22 | O12: 0.591 | P12: 4 | Q12: 7 | R12: 0.571 | S12: 9 | T12: 15 | U12: 0.6 | V12: 0.682 | W12: 5 | X12: 8 | Y12: 0.625 | Z12: 1 | AA12: 11 | AB12: 12 | AC12: 14 | AD12: 1 | AE12: 0 | AF12: 6 | AG12: 2 | AH12: 35 | AI12: 31.6 | AJ12: 3
A13: 12 | B13: 12 | C13: 45611 | D13: No Luka | E13: Regular | F13: LAL | G13: @ | H13: SAS | I13: W | J13: 120-115 | K13: * | L13: 37.816667 | M13: 6 | N13: 12 | O13: 0.5 | P13: 1 | Q13: 4 | R13: 0.25 | S13: 5 | T13: 8 | U13: 0.625 | V13: 0.542 | W13: 2 | X13: 4 | Y13: 0.5 | Z13: 1 | AA13: 15 | AB13: 16 | AC13: 12 | AD13: 1 | AE13: 0 | AF13: 7 | AG13: 0 | AH13: 15 | AI13: 15.8 | AJ13: 3
A14: 13 | B14: 13 | C14: 45612 | D14: No Luka | E14: Regular | F14: LAL | G14: @ | H14: NOP | I14: W | J14: 104-99 | K14: * | L14: 37.033333 | M14: 8 | N14: 19 | O14: 0.421 | P14: 2 | Q14: 7 | R14: 0.286 | S14: 6 | T14: 12 | U14: 0.5 | V14: 0.474 | W14: 3 | X14: 5 | Y14: 0.6 | Z14: 4 | AA14: 3 | AB14: 7 | AC14: 5 | AD14: 1 | AE14: 0 | AF14: 6 | AG14: 1 | AH14: 21 | AI14: 11.9 | AJ14: 1
A15: 14 | B15: 14 | C15: 45615 | D15: No Luka | E15: Regular | F15: LAL | H15: UTA | I15: W | J15: 124-118 | K15: * | L15: 33.883333 | M15: 9 | N15: 17 | O15: 0.529 | P15: 1 | Q15: 5 | R15: 0.2 | S15: 8 | T15: 12 | U15: 0.667 | V15: 0.559 | W15: 7 | X15: 11 | Y15: 0.636 | Z15: 0 | AA15: 2 | AB15: 2 | AC15: 12 | AD15: 0 | AE15: 0 | AF15: 4 | AG15: 1 | AH15: 26 | AI15: 20.7 | AJ15: -5
A16: 15 | B16: 15 | C16: 45617 | D16: No Luka | E16: Regular | F16: LAL | H16: ORL | I16: L | J16: 118-119 | K16: * | L16: 37.033333 | M16: 12 | N16: 22 | O16: 0.545 | P16: 5 | Q16: 9 | R16: 0.556 | S16: 7 | T16: 13 | U16: 0.538 | V16: 0.659 | W16: 2 | X16: 4 | Y16: 0.5 | Z16: 2 | AA16: 8 | AB16: 10 | AC16: 7 | AD16: 0 | AE16: 1 | AF16: 4 | AG16: 0 | AH16: 31 | AI16: 25 | AJ16: -8
A17: 16 | B17: 16 | C17: 45619 | D17: No Luka | E17: Regular | F17: LAL | H17: DEN | I17: L | J17: 102-127 | K17: * | L17: 34.683333 | M17: 7 | N17: 17 | O17: 0.412 | P17: 1 | Q17: 4 | R17: 0.25 | S17: 6 | T17: 13 | U17: 0.462 | V17: 0.441 | W17: 3 | X17: 3 | Y17: 1 | Z17: 0 | AA17: 6 | AB17: 6 | AC17: 7 | AD17: 3 | AE17: 0 | AF17: 6 | AG17: 3 | AH17: 18 | AI17: 11.4 | AJ17: -25
A18: 17 | B18: 17 | C18: 45622 | D18: No Luka | E18: Regular | F18: LAL | G18: @ | H18: PHO | I18: L | J18: 100-127 | K18: * | L18: 34.733333 | M18: 7 | N18: 16 | O18: 0.438 | P18: 2 | Q18: 7 | R18: 0.286 | S18: 5 | T18: 9 | U18: 0.556 | V18: 0.5 | W18: 2 | X18: 2 | Y18: 1 | Z18: 1 | AA18: 7 | AB18: 8 | AC18: 10 | AD18: 0 | AE18: 0 | AF18: 5 | AG18: 0 | AH18: 18 | AI18: 14.4 | AJ18: -30
A19: 18 | B19: 18 | C19: 45623 | D19: No Luka | E19: Regular | F19: LAL | G19: @ | H19: SAS | I19: W | J19: 119-101 | K19: * | L19: 33.083333 | M19: 8 | N19: 18 | O19: 0.444 | P19: 0 | Q19: 2 | R19: 0 | S19: 8 | T19: 16 | U19: 0.5 | V19: 0.444 | W19: 0 | X19: 0 | Z19: 3 | AA19: 7 | AB19: 10 | AC19: 11 | AD19: 1 | AE19: 1 | AF19: 5 | AG19: 0 | AH19: 16 | AI19: 15.2 | AJ19: 4
A20: 19 | B20: 19 | C20: 45625 | D20: No Luka | E20: Regular | F20: LAL | H20: OKC | I20: L | J20: 93-101 | K20: * | L20: 33.516667 | M20: 5 | N20: 13 | O20: 0.385 | P20: 0 | Q20: 4 | R20: 0 | S20: 5 | T20: 9 | U20: 0.556 | V20: 0.385 | W20: 2 | X20: 2 | Y20: 1 | Z20: 0 | AA20: 8 | AB20: 8 | AC20: 6 | AD20: 0 | AE20: 0 | AF20: 5 | AG20: 0 | AH20: 12 | AI20: 6.5 | AJ20: -12
A21: 20 | B21: 20 | C21: 45627 | D21: No Luka | E21: Regular | F21: LAL | G21: @ | H21: UTA | I21: W | J21: 105-104 | K21: * | L21: 36.066667 | M21: 12 | N21: 28 | O21: 0.429 | P21: 0 | Q21: 9 | R21: 0 | S21: 12 | T21: 19 | U21: 0.632 | V21: 0.429 | W21: 3 | X21: 3 | Y21: 1 | Z21: 1 | AA21: 4 | AB21: 5 | AC21: 14 | AD21: 0 | AE21: 2 | AF21: 3 | AG21: 1 | AH21: 27 | AI21: 21.9 | AJ21: 0
A22: 21 | B22: 21 | C22: 45628 | D22: No Luka | E22: Regular | F22: LAL | G22: @ | H22: MIN | I22: L | J22: 80-109 | K22: * | L22: 30.733333 | M22: 4 | N22: 16 | O22: 0.25 | P22: 0 | Q22: 4 | R22: 0 | S22: 4 | T22: 12 | U22: 0.333 | V22: 0.25 | W22: 2 | X22: 4 | Y22: 0.5 | Z22: 3 | AA22: 5 | AB22: 8 | AC22: 4 | AD22: 0 | AE22: 0 | AF22: 6 | AG22: 1 | AH22: 10 | AI22: -0.4 | AJ22: -28
A23: 22 | B23: 22 | C23: 45630 | D23: No Luka | E23: Regular | F23: LAL | G23: @ | H23: MIA | I23: L | J23: 93-134 | K23: * | L23: 29.05 | M23: 12 | N23: 18 | O23: 0.667 | P23: 1 | Q23: 4 | R23: 0.25 | S23: 11 | T23: 14 | U23: 0.786 | V23: 0.694 | W23: 4 | X23: 4 | Y23: 1 | Z23: 1 | AA23: 4 | AB23: 5 | AC23: 8 | AD23: 1 | AE23: 0 | AF23: 5 | AG23: 2 | AH23: 29 | AI23: 23.9 | AJ23: -21
A24: 23 | B24: 23 | C24: 45632 | D24: No Luka | E24: Regular | F24: LAL | G24: @ | H24: ATL | I24: L | J24: 132-134 (OT) | K24: * | L24: 43.366667 | M24: 14 | N24: 25 | O24: 0.56 | P24: 6 | Q24: 11 | R24: 0.545 | S24: 8 | T24: 14 | U24: 0.571 | V24: 0.68 | W24: 5 | X24: 6 | Y24: 0.833 | Z24: 0 | AA24: 10 | AB24: 10 | AC24: 11 | AD24: 2 | AE24: 3 | AF24: 4 | AG24: 3 | AH24: 39 | AI24: 36.3 | AJ24: 3
A25: 23 | B25: 24 | C25: 45634 | D25: No Luka | E25: Regular | F25: LAL | H25: POR | I25: W | J25: 107-98 | K25: Inactive
A26: 23 | B26: 25 | C26: 45639 | D26: No Luka | E26: Regular | F26: LAL | G26: @ | H26: MIN | I26: L | J26: 87-97 | K26: Inactive
A27: 24 | B27: 26 | C27: 45641 | D27: No Luka | E27: Regular | F27: LAL | H27: MEM | I27: W | J27: 116-110 | K27: * | L27: 34 | M27: 7 | N27: 17 | O27: 0.412 | P27: 3 | Q27: 6 | R27: 0.5 | S27: 4 | T27: 11 | U27: 0.364 | V27: 0.5 | W27: 1 | X27: 4 | Y27: 0.25 | Z27: 4 | AA27: 4 | AB27: 8 | AC27: 8 | AD27: 1 | AE27: 2 | AF27: 5 | AG27: 2 | AH27: 18 | AI27: 13.9 | AJ27: 0
A28: 25 | B28: 27 | C28: 45645 | D28: No Luka | E28: Regular | F28: LAL | G28: @ | H28: SAC | I28: W | J28: 113-100 | K28: * | L28: 34.083333 | M28: 8 | N28: 21 | O28: 0.381 | P28: 1 | Q28: 4 | R28: 0.25 | S28: 7 | T28: 17 | U28: 0.412 | V28: 0.405 | W28: 2 | X28: 2 | Y28: 1 | Z28: 0 | AA28: 6 | AB28: 6 | AC28: 7 | AD28: 0 | AE28: 1 | AF28: 2 | AG28: 1 | AH28: 19 | AI28: 12.5 | AJ28: 13
A29: 26 | B29: 28 | C29: 45647 | D29: No Luka | E29: Regular | F29: LAL | G29: @ | H29: SAC | I29: W | J29: 103-99 | K29: * | L29: 34.416667 | M29: 13 | N29: 24 | O29: 0.542 | P29: 1 | Q29: 8 | R29: 0.125 | S29: 12 | T29: 16 | U29: 0.75 | V29: 0.563 | W29: 5 | X29: 6 | Y29: 0.833 | Z29: 0 | AA29: 7 | AB29: 7 | AC29: 6 | AD29: 4 | AE29: 0 | AF29: 4 | AG29: 2 | AH29: 32 | AI29: 25.5 | AJ29: 10
A30: 27 | B30: 29 | C30: 45649 | D30: No Luka | E30: Regular | F30: LAL | H30: DET | I30: L | J30: 114-117 | K30: * | L30: 35.433333 | M30: 10 | N30: 16 | O30: 0.625 | P30: 2 | Q30: 4 | R30: 0.5 | S30: 8 | T30: 12 | U30: 0.667 | V30: 0.688 | W30: 6 | X30: 7 | Y30: 0.857 | Z30: 2 | AA30: 9 | AB30: 11 | AC30: 11 | AD30: 0 | AE30: 0 | AF30: 2 | AG30: 1 | AH30: 28 | AI30: 29.8 | AJ30: -1
A31: 28 | B31: 30 | C31: 45651 | D31: No Luka | E31: Regular | F31: LAL | G31: @ | H31: GSW | I31: W | J31: 115-113 | K31: * | L31: 36.966667 | M31: 12 | N31: 22 | O31: 0.545 | P31: 2 | Q31: 4 | R31: 0.5 | S31: 10 | T31: 18 | U31: 0.556 | V31: 0.591 | W31: 5 | X31: 5 | Y31: 1 | Z31: 0 | AA31: 4 | AB31: 4 | AC31: 10 | AD31: 2 | AE31: 1 | AF31: 1 | AG31: 3 | AH31: 31 | AI31: 29.1 | AJ31: 4
A32: 28 | B32: 31 | C32: 45654 | D32: No Luka | E32: Regular | F32: LAL | H32: SAC | I32: W | J32: 132-122 | K32: Inactive
A33: 29 | B33: 32 | C33: 45657 | D33: No Luka | E33: Regular | F33: LAL | H33: CLE | I33: L | J33: 110-122 | K33: * | L33: 34.2 | M33: 9 | N33: 17 | O33: 0.529 | P33: 3 | Q33: 6 | R33: 0.5 | S33: 6 | T33: 11 | U33: 0.545 | V33: 0.618 | W33: 2 | X33: 2 | Y33: 1 | Z33: 0 | AA33: 4 | AB33: 4 | AC33: 7 | AD33: 0 | AE33: 1 | AF33: 2 | AG33: 1 | AH33: 23 | AI33: 19.1 | AJ33: -11
A34: 30 | B34: 33 | C34: 45659 | D34: No Luka | E34: Regular | F34: LAL | H34: POR | I34: W | J34: 114-106 | K34: * | L34: 36.2 | M34: 15 | N34: 25 | O34: 0.6 | P34: 7 | Q34: 10 | R34: 0.7 | S34: 8 | T34: 15 | U34: 0.533 | V34: 0.74 | W34: 1 | X34: 2 | Y34: 0.5 | Z34: 1 | AA34: 2 | AB34: 3 | AC34: 8 | AD34: 0 | AE34: 0 | AF34: 4 | AG34: 1 | AH34: 38 | AI34: 28.6 | AJ34: 4
A35: 31 | B35: 34 | C35: 45660 | D35: No Luka | E35: Regular | F35: LAL | H35: ATL | I35: W | J35: 119-102 | K35: * | L35: 30 | M35: 13 | N35: 20 | O35: 0.65 | P35: 2 | Q35: 5 | R35: 0.4 | S35: 11 | T35: 15 | U35: 0.733 | V35: 0.7 | W35: 2 | X35: 2 | Y35: 1 | Z35: 0 | AA35: 3 | AB35: 3 | AC35: 8 | AD35: 0 | AE35: 0 | AF35: 3 | AG35: 3 | AH35: 30 | AI35: 23.5 | AJ35: 4
A36: 32 | B36: 35 | C36: 45662 | D36: No Luka | E36: Regular | F36: LAL | G36: @ | H36: HOU | I36: L | J36: 115-119 | K36: * | L36: 36.05 | M36: 8 | N36: 16 | O36: 0.5 | P36: 4 | Q36: 7 | R36: 0.571 | S36: 4 | T36: 9 | U36: 0.444 | V36: 0.625 | W36: 1 | X36: 2 | Y36: 0.5 | Z36: 1 | AA36: 12 | AB36: 13 | AC36: 9 | AD36: 1 | AE36: 0 | AF36: 2 | AG36: 4 | AH36: 21 | AI36: 20.6 | AJ36: -13
A37: 33 | B37: 36 | C37: 45664 | D37: No Luka | E37: Regular | F37: LAL | G37: @ | H37: DAL | I37: L | J37: 97-118 | K37: * | L37: 34.866667 | M37: 6 | N37: 12 | O37: 0.5 | P37: 1 | Q37: 4 | R37: 0.25 | S37: 5 | T37: 8 | U37: 0.625 | V37: 0.542 | W37: 5 | X37: 6 | Y37: 0.833 | Z37: 0 | AA37: 10 | AB37: 10 | AC37: 8 | AD37: 1 | AE37: 0 | AF37: 2 | AG37: 0 | AH37: 18 | AI37: 19.2 | AJ37: -12
A38: 34 | B38: 37 | C38: 45670 | D38: No Luka | E38: Regular | F38: LAL | H38: SAS | I38: L | J38: 102-126 | K38: * | L38: 32.1 | M38: 7 | N38: 11 | O38: 0.636 | P38: 2 | Q38: 3 | R38: 0.667 | S38: 5 | T38: 8 | U38: 0.625 | V38: 0.727 | W38: 2 | X38: 4 | Y38: 0.5 | Z38: 1 | AA38: 4 | AB38: 5 | AC38: 8 | AD38: 1 | AE38: 1 | AF38: 7 | AG38: 3 | AH38: 18 | AI38: 13.3 | AJ38: -15
A39: 35 | B39: 38 | C39: 45672 | D39: No Luka | E39: Regular | F39: LAL | H39: MIA | I39: W | J39: 117-108 | K39: * | L39: 38.15 | M39: 9 | N39: 15 | O39: 0.6 | P39: 3 | Q39: 6 | R39: 0.5 | S39: 6 | T39: 9 | U39: 0.667 | V39: 0.7 | W39: 1 | X39: 2 | Y39: 0.5 | Z39: 1 | AA39: 4 | AB39: 5 | AC39: 9 | AD39: 2 | AE39: 0 | AF39: 2 | AG39: 0 | AH39: 22 | AI39: 22.9 | AJ39: 14
A40: 36 | B40: 39 | C40: 45674 | D40: No Luka | E40: Regular | F40: LAL | H40: BRK | I40: W | J40: 102-101 | K40: * | L40: 34.933333 | M40: 12 | N40: 17 | O40: 0.706 | P40: 4 | Q40: 6 | R40: 0.667 | S40: 8 | T40: 11 | U40: 0.727 | V40: 0.824 | W40: 1 | X40: 2 | Y40: 0.5 | Z40: 1 | AA40: 6 | AB40: 7 | AC40: 8 | AD40: 1 | AE40: 2 | AF40: 5 | AG40: 2 | AH40: 29 | AI40: 26.2 | AJ40: -11
...

Sheet AR_REG_OFFS 
A1: Rk | B1: Date | C1: Column1 | D1: SEASON TYPE | E1: Team | F1: @ | G1: Opp | H1: W/L | I1: Result.2 | J1: GS | K1: Column3 | L1: FG | M1: FGA | N1: FG% | O1: 3P | P1: 3PA | Q1: 3P% | R1: 2P | S1: 2PA | T1: 2P% | U1: eFG% | V1: FT | W1: FTA | X1: FT% | Y1: ORB | Z1: DRB | AA1: TRB | AB1: AST | AC1: STL | AD1: BLK | AE1: TOV | AF1: PF | AG1: PTS | AH1: GmSc | AI1: +/-
A2: 1 | B2: 45587 | C2: No Luka | D2: REGULAR | E2: LAL | G2: MIN | H2: W | I2: 110-103 | J2: * | K2: 36.033333 | L2: 6 | M2: 14 | N2: 0.429 | O2: 0 | P2: 5 | Q2: 0 | R2: 6 | S2: 9 | T2: 0.667 | U2: 0.429 | V2: 0 | W2: 1 | X2: 0 | Y2: 4 | Z2: 5 | AA2: 9 | AB2: 4 | AC2: 1 | AD2: 1 | AE2: 0 | AF2: 4 | AG2: 12 | AH2: 11.4 | AI2: 12
A3: 2 | B3: 45590 | C3: No Luka | D3: REGULAR | E3: LAL | G3: PHO | H3: W | I3: 123-116 | J3: * | K3: 36.65 | L3: 8 | M3: 12 | N3: 0.667 | O3: 5 | P3: 7 | Q3: 0.714 | R3: 3 | S3: 5 | T3: 0.6 | U3: 0.875 | V3: 5 | W3: 6 | X3: 0.833 | Y3: 0 | Z3: 4 | AA3: 4 | AB3: 8 | AC3: 3 | AD3: 1 | AE3: 4 | AF3: 4 | AG3: 26 | AH3: 25.3 | AI3: 13
A4: 3 | B4: 45591 | C4: No Luka | D4: REGULAR | E4: LAL | G4: SAC | H4: W | I4: 131-127 | J4: * | K4: 33.533333 | L4: 7 | M4: 12 | N4: 0.583 | O4: 2 | P4: 4 | Q4: 0.5 | R4: 5 | S4: 8 | T4: 0.625 | U4: 0.667 | V4: 0 | W4: 0 | Y4: 4 | Z4: 3 | AA4: 7 | AB4: 6 | AC4: 0 | AD4: 0 | AE4: 6 | AF4: 3 | AG4: 16 | AH4: 11.1 | AI4: -20
A5: 4 | B5: 45593 | C5: No Luka | D5: REGULAR | E5: LAL | F5: @ | G5: PHO | H5: L | I5: 105-109 | J5: * | K5: 37.85 | L5: 8 | M5: 15 | N5: 0.533 | O5: 5 | P5: 9 | Q5: 0.556 | R5: 3 | S5: 6 | T5: 0.5 | U5: 0.7 | V5: 2 | W5: 3 | X5: 0.667 | Y5: 0 | Z5: 8 | AA5: 8 | AB5: 3 | AC5: 2 | AD5: 0 | AE5: 1 | AF5: 3 | AG5: 23 | AH5: 19.6 | AI5: 12
A6: 5 | B6: 45595 | C6: No Luka | D6: REGULAR | E6: LAL | F6: @ | G6: CLE | H6: L | I6: 110-134 | J6: * | K6: 27.833333 | L6: 2 | M6: 6 | N6: 0.333 | O6: 1 | P6: 4 | Q6: 0.25 | R6: 1 | S6: 2 | T6: 0.5 | U6: 0.417 | V6: 2 | W6: 2 | X6: 1 | Y6: 0 | Z6: 2 | AA6: 2 | AB6: 3 | AC6: 0 | AD6: 0 | AE6: 4 | AF6: 0 | AG6: 7 | AH6: 2.3 | AI6: -14
A7: 6 | B7: 45597 | C7: No Luka | D7: REGULAR | E7: LAL | F7: @ | G7: TOR | H7: W | I7: 131-125 | J7: * | K7: 34.3 | L7: 4 | M7: 13 | N7: 0.308 | O7: 0 | P7: 6 | Q7: 0 | R7: 4 | S7: 7 | T7: 0.571 | U7: 0.308 | V7: 12 | W7: 14 | X7: 0.857 | Y7: 0 | Z7: 1 | AA7: 1 | AB7: 6 | AC7: 2 | AD7: 1 | AE7: 1 | AF7: 3 | AG7: 20 | AH7: 16.7 | AI7: -3
A8: 7 | B8: 45600 | C8: No Luka | D8: REGULAR | E8: LAL | F8: @ | G8: DET | H8: L | I8: 103-115 | J8: * | K8: 39.35 | L8: 7 | M8: 17 | N8: 0.412 | O8: 3 | P8: 10 | Q8: 0.3 | R8: 4 | S8: 7 | T8: 0.571 | U8: 0.5 | V8: 0 | W8: 1 | X8: 0 | Y8: 1 | Z8: 3 | AA8: 4 | AB8: 4 | AC8: 2 | AD8: 0 | AE8: 4 | AF8: 4 | AG8: 17 | AH8: 8.3 | AI8: -14
A9: 8 | B9: 45602 | C9: No Luka | D9: REGULAR | E9: LAL | F9: @ | G9: MEM | H9: L | I9: 114-131 | J9: * | K9: 34.933333 | L9: 7 | M9: 17 | N9: 0.412 | O9: 2 | P9: 9 | Q9: 0.222 | R9: 5 | S9: 8 | T9: 0.625 | U9: 0.471 | V9: 3 | W9: 4 | X9: 0.75 | Y9: 0 | Z9: 3 | AA9: 3 | AB9: 5 | AC9: 3 | AD9: 0 | AE9: 1 | AF9: 1 | AG9: 19 | AH9: 15.5 | AI9: -9
A10: 9 | B10: 45604 | C10: No Luka | D10: REGULAR | E10: LAL | G10: PHI | H10: W | I10: 116-106 | J10: * | K10: 29.933333 | L10: 7 | M10: 13 | N10: 0.538 | O10: 6 | P10: 10 | Q10: 0.6 | R10: 1 | S10: 3 | T10: 0.333 | U10: 0.769 | V10: 0 | W10: 0 | Y10: 0 | Z10: 6 | AA10: 6 | AB10: 7 | AC10: 0 | AD10: 1 | AE10: 2 | AF10: 1 | AG10: 20 | AH10: 18.7 | AI10: 14
A11: 10 | B11: 45606 | C11: No Luka | D11: REGULAR | E11: LAL | G11: TOR | H11: W | I11: 123-103 | J11: * | K11: 32.583333 | L11: 10 | M11: 17 | N11: 0.588 | O11: 3 | P11: 9 | Q11: 0.333 | R11: 7 | S11: 8 | T11: 0.875 | U11: 0.676 | V11: 4 | W11: 5 | X11: 0.8 | Y11: 0 | Z11: 1 | AA11: 1 | AB11: 6 | AC11: 1 | AD11: 0 | AE11: 0 | AF11: 4 | AG11: 27 | AH11: 22.6 | AI11: 11
A12: 11 | B12: 45609 | C12: No Luka | D12: REGULAR | E12: LAL | G12: MEM | H12: W | I12: 128-123 | J12: * | K12: 35.866667 | L12: 5 | M12: 14 | N12: 0.357 | O12: 3 | P12: 11 | Q12: 0.273 | R12: 2 | S12: 3 | T12: 0.667 | U12: 0.464 | V12: 5 | W12: 7 | X12: 0.714 | Y12: 0 | Z12: 2 | AA12: 2 | AB12: 6 | AC12: 1 | AD12: 0 | AE12: 3 | AF12: 4 | AG12: 18 | AH12: 10.6 | AI12: -1
A13: 12 | B13: 45611 | C13: No Luka | D13: REGULAR | E13: LAL | F13: @ | G13: SAS | H13: W | I13: 120-115 | J13: * | K13: 32.066667 | L13: 6 | M13: 12 | N13: 0.5 | O13: 5 | P13: 9 | Q13: 0.556 | R13: 1 | S13: 3 | T13: 0.333 | U13: 0.708 | V13: 2 | W13: 2 | X13: 1 | Y13: 1 | Z13: 2 | AA13: 3 | AB13: 6 | AC13: 0 | AD13: 0 | AE13: 0 | AF13: 3 | AG13: 19 | AH13: 17.3 | AI13: -8
A14: 13 | B14: 45612 | C14: No Luka | D14: REGULAR | E14: LAL | F14: @ | G14: NOP | H14: W | I14: 104-99 | J14: * | K14: 40.833333 | L14: 3 | M14: 15 | N14: 0.2 | O14: 2 | P14: 9 | Q14: 0.222 | R14: 1 | S14: 6 | T14: 0.167 | U14: 0.267 | V14: 2 | W14: 2 | X14: 1 | Y14: 1 | Z14: 1 | AA14: 2 | AB14: 7 | AC14: 1 | AD14: 0 | AE14: 0 | AF14: 1 | AG14: 10 | AH14: 7.2 | AI14: 9
A15: 14 | B15: 45615 | C15: No Luka | D15: REGULAR | E15: LAL | G15: UTA | H15: W | I15: 124-118 | J15: * | K15: 33.366667 | L15: 6 | M15: 14 | N15: 0.429 | O15: 3 | P15: 7 | Q15: 0.429 | R15: 3 | S15: 7 | T15: 0.429 | U15: 0.536 | V15: 2 | W15: 2 | X15: 1 | Y15: 0 | Z15: 0 | AA15: 0 | AB15: 5 | AC15: 0 | AD15: 0 | AE15: 3 | AF15: 1 | AG15: 17 | AH15: 9.7 | AI15: 4
A16: 15 | B16: 45617 | C16: No Luka | D16: REGULAR | E16: LAL | G16: ORL | H16: L | I16: 118-119 | J16: * | K16: 32.9 | L16: 3 | M16: 12 | N16: 0.25 | O16: 1 | P16: 4 | Q16: 0.25 | R16: 2 | S16: 8 | T16: 0.25 | U16: 0.292 | V16: 2 | W16: 5 | X16: 0.4 | Y16: 1 | Z16: 1 | AA16: 2 | AB16: 3 | AC16: 1 | AD16: 0 | AE16: 2 | AF16: 0 | AG16: 9 | AH16: 2.7 | AI16: -8
A17: 16 | B17: 45619 | C17: No Luka | D17: REGULAR | E17: LAL | G17: DEN | H17: L | I17: 102-127 | J17: * | K17: 31.85 | L17: 7 | M17: 13 | N17: 0.538 | O17: 3 | P17: 7 | Q17: 0.429 | R17: 4 | S17: 6 | T17: 0.667 | U17: 0.654 | V17: 2 | W17: 2 | X17: 1 | Y17: 1 | Z17: 2 | AA17: 3 | AB17: 6 | AC17: 1 | AD17: 0 | AE17: 3 | AF17: 1 | AG17: 19 | AH17: 15.8 | AI17: -22
A18: 17 | B18: 45622 | C18: No Luka | D18: REGULAR | E18: LAL | F18: @ | G18: PHO | H18: L | I18: 100-127 | J18: * | K18: 30.6 | L18: 6 | M18: 12 | N18: 0.5 | O18: 2 | P18: 6 | Q18: 0.333 | R18: 4 | S18: 6 | T18: 0.667 | U18: 0.583 | V18: 1 | W18: 1 | X18: 1 | Y18: 1 | Z18: 2 | AA18: 3 | AB18: 2 | AC18: 2 | AD18: 0 | AE18: 1 | AF18: 0 | AG18: 15 | AH18: 12.7 | AI18: -16
A19: 18 | B19: 45623 | C19: No Luka | D19: REGULAR | E19: LAL | F19: @ | G19: SAS | H19: W | I19: 119-101 | J19: * | K19: 31.45 | L19: 5 | M19: 11 | N19: 0.455 | O19: 3 | P19: 6 | Q19: 0.5 | R19: 2 | S19: 5 | T19: 0.4 | U19: 0.591 | V19: 0 | W19: 0 | Y19: 0 | Z19: 2 | AA19: 2 | AB19: 2 | AC19: 0 | AD19: 0 | AE19: 3 | AF19: 1 | AG19: 13 | AH19: 5.9 | AI19: 8
A20: 19 | B20: 45625 | C20: No Luka | D20: REGULAR | E20: LAL | G20: OKC | H20: L | I20: 93-101 | J20: * | K20: 29.183333 | L20: 3 | M20: 11 | N20: 0.273 | O20: 1 | P20: 9 | Q20: 0.111 | R20: 2 | S20: 2 | T20: 1 | U20: 0.318 | V20: 4 | W20: 5 | X20: 0.8 | Y20: 1 | Z20: 4 | AA20: 5 | AB20: 3 | AC20: 0 | AD20: 0 | AE20: 5 | AF20: 3 | AG20: 11 | AH20: 1.9 | AI20: -8
A21: 19 | B21: 45627 | C21: No Luka | D21: REGULAR | E21: LAL | F21: @ | G21: UTA | H21: W | I21: 105-104 | J21: Inactive | K21: 0
A22: 19 | B22: 45628 | C22: No Luka | D22: REGULAR | E22: LAL | F22: @ | G22: MIN | H22: L | I22: 80-109 | J22: Inactive | K22: 0
A23: 19 | B23: 45630 | C23: No Luka | D23: REGULAR | E23: LAL | F23: @ | G23: MIA | H23: L | I23: 93-134 | J23: Inactive | K23: 0
A24: 19 | B24: 45632 | C24: No Luka | D24: REGULAR | E24: LAL | F24: @ | G24: ATL | H24: L | I24: 132-134 (OT) | J24: Inactive | K24: 0
A25: 19 | B25: 45634 | C25: No Luka | D25: REGULAR | E25: LAL | G25: POR | H25: W | I25: 107-98 | J25: Inactive | K25: 0
A26: 20 | B26: 45639 | C26: No Luka | D26: REGULAR | E26: LAL | F26: @ | G26: MIN | H26: L | I26: 87-97 | J26: * | K26: 29.666667 | L26: 6 | M26: 16 | N26: 0.375 | O26: 4 | P26: 8 | Q26: 0.5 | R26: 2 | S26: 8 | T26: 0.25 | U26: 0.5 | V26: 2 | W26: 2 | X26: 1 | Y26: 2 | Z26: 4 | AA26: 6 | AB26: 6 | AC26: 0 | AD26: 0 | AE26: 2 | AF26: 5 | AG26: 18 | AH26: 12 | AI26: -2
A27: 21 | B27: 45641 | C27: No Luka | D27: REGULAR | E27: LAL | G27: MEM | H27: W | I27: 116-110 | J27: * | K27: 35.766667 | L27: 6 | M27: 15 | N27: 0.4 | O27: 2 | P27: 8 | Q27: 0.25 | R27: 4 | S27: 7 | T27: 0.571 | U27: 0.467 | V27: 5 | W27: 5 | X27: 1 | Y27: 0 | Z27: 2 | AA27: 2 | AB27: 8 | AC27: 2 | AD27: 0 | AE27: 1 | AF27: 4 | AG27: 19 | AH27: 16.5 | AI27: 11
A28: 22 | B28: 45645 | C28: No Luka | D28: REGULAR | E28: LAL | F28: @ | G28: SAC | H28: W | I28: 113-100 | J28: * | K28: 34.916667 | L28: 7 | M28: 14 | N28: 0.5 | O28: 3 | P28: 7 | Q28: 0.429 | R28: 4 | S28: 7 | T28: 0.571 | U28: 0.607 | V28: 8 | W28: 9 | X28: 0.889 | Y28: 0 | Z28: 6 | AA28: 6 | AB28: 5 | AC28: 2 | AD28: 0 | AE28: 1 | AF28: 0 | AG28: 25 | AH28: 23.9 | AI28: 9
A29: 23 | B29: 45647 | C29: No Luka | D29: REGULAR | E29: LAL | F29: @ | G29: SAC | H29: W | I29: 103-99 | J29: * | K29: 35.933333 | L29: 6 | M29: 14 | N29: 0.429 | O29: 1 | P29: 7 | Q29: 0.143 | R29: 5 | S29: 7 | T29: 0.714 | U29: 0.464 | V29: 3 | W29: 5 | X29: 0.6 | Y29: 2 | Z29: 2 | AA29: 4 | AB29: 5 | AC29: 0 | AD29: 0 | AE29: 2 | AF29: 1 | AG29: 16 | AH29: 10.9 | AI29: 10
A30: 24 | B30: 45649 | C30: No Luka | D30: REGULAR | E30: LAL | G30: DET | H30: L | I30: 114-117 | J30: * | K30: 36.883333 | L30: 5 | M30: 9 | N30: 0.556 | O30: 2 | P30: 5 | Q30: 0.4 | R30: 3 | S30: 4 | T30: 0.75 | U30: 0.667 | V30: 0 | W30: 0 | Y30: 0 | Z30: 7 | AA30: 7 | AB30: 2 | AC30: 2 | AD30: 0 | AE30: 6 | AF30: 2 | AG30: 12 | AH30: 6.4 | AI30: 16
A31: 25 | B31: 45651 | C31: No Luka | D31: REGULAR | E31: LAL | F31: @ | G31: GSW | H31: W | I31: 115-113 | J31: * | K31: 36.666667 | L31: 8 | M31: 20 | N31: 0.4 | O31: 4 | P31: 10 | Q31: 0.4 | R31: 4 | S31: 10 | T31: 0.4 | U31: 0.5 | V31: 6 | W31: 6 | X31: 1 | Y31: 2 | Z31: 8 | AA31: 10 | AB31: 10 | AC31: 1 | AD31: 0 | AE31: 3 | AF31: 0 | AG31: 26 | AH31: 24 | AI31: -4
A32: 26 | B32: 45654 | C32: No Luka | D32: REGULAR | E32: LAL | G32: SAC | H32: W | I32: 132-122 | J32: * | K32: 42.6 | L32: 9 | M32: 16 | N32: 0.563 | O32: 3 | P32: 4 | Q32: 0.75 | R32: 6 | S32: 12 | T32: 0.5 | U32: 0.656 | V32: 5 | W32: 8 | X32: 0.625 | Y32: 1 | Z32: 5 | AA32: 6 | AB32: 16 | AC32: 0 | AD32: 0 | AE32: 5 | AF32: 3 | AG32: 26 | AH32: 24.4 | AI32: 15
A33: 27 | B33: 45657 | C33: No Luka | D33: REGULAR | E33: LAL | G33: CLE | H33: L | I33: 110-122 | J33: * | K33: 37.95 | L33: 11 | M33: 20 | N33: 0.55 | O33: 1 | P33: 4 | Q33: 0.25 | R33: 10 | S33: 16 | T33: 0.625 | U33: 0.575 | V33: 12 | W33: 13 | X33: 0.923 | Y33: 1 | Z33: 8 | AA33: 9 | AB33: 10 | AC33: 1 | AD33: 0 | AE33: 4 | AF33: 2 | AG33: 35 | AH33: 31.3 | AI33: -3
A34: 28 | B34: 45659 | C34: No Luka | D34: REGULAR | E34: LAL | G34: POR | H34: W | I34: 114-106 | J34: * | K34: 36.433333 | L34: 5 | M34: 15 | N34: 0.333 | O34: 2 | P34: 9 | Q34: 0.222 | R34: 3 | S34: 6 | T34: 0.5 | U34: 0.4 | V34: 3 | W34: 3 | X34: 1 | Y34: 2 | Z34: 6 | AA34: 8 | AB34: 11 | AC34: 2 | AD34: 0 | AE34: 3 | AF34: 3 | AG34: 15 | AH34: 15.2 | AI34: 10
A35: 29 | B35: 45660 | C35: No Luka | D35: REGULAR | E35: LAL | G35: ATL | H35: W | I35: 119-102 | J35: * | K35: 38.65 | L35: 6 | M35: 18 | N35: 0.333 | O35: 3 | P35: 7 | Q35: 0.429 | R35: 3 | S35: 11 | T35: 0.273 | U35: 0.417 | V35: 5 | W35: 6 | X35: 0.833 | Y35: 4 | Z35: 3 | AA35: 7 | AB35: 6 | AC35: 0 | AD35: 0 | AE35: 6 | AF35: 1 | AG35: 20 | AH35: 10.9 | AI35: 18
A36: 30 | B36: 45662 | C36: No Luka | D36: REGULAR | E36: LAL | F36: @ | G36: HOU | H36: L | I36: 115-119 | J36: * | K36: 41.316667 | L36: 6 | M36: 13 | N36: 0.462 | O36: 3 | P36: 6 | Q36: 0.5 | R36: 3 | S36: 7 | T36: 0.429 | U36: 0.577 | V36: 6 | W36: 7 | X36: 0.857 | Y36: 0 | Z36: 0 | AA36: 0 | AB36: 10 | AC36: 0 | AD36: 0 | AE36: 0 | AF36: 2 | AG36: 21 | AH36: 20.1 | AI36: 12
A37: 31 | B37: 45664 | C37: No Luka | D37: REGULAR | E37: LAL | F37: @ | G37: DAL | H37: L | I37: 97-118 | J37: * | K37: 32.083333 | L37: 5 | M37: 14 | N37: 0.357 | O37: 4 | P37: 11 | Q37: 0.364 | R37: 1 | S37: 3 | T37: 0.333 | U37: 0.5 | V37: 1 | W37: 2 | X37: 0.5 | Y37: 0 | Z37: 2 | AA37: 2 | AB37: 1 | AC37: 3 | AD37: 0 | AE37: 1 | AF37: 1 | AG37: 15 | AH37: 9.7 | AI37: -25
A38: 32 | B38: 45670 | C38: No Luka | D38: REGULAR | E38: LAL | G38: SAS | H38: L | I38: 102-126 | J38: * | K38: 33.483333 | L38: 4 | M38: 13 | N38: 0.308 | O38: 2 | P38: 7 | Q38: 0.286 | R38: 2 | S38: 6 | T38: 0.333 | U38: 0.385 | V38: 2 | W38: 2 | X38: 1 | Y38: 1 | Z38: 4 | AA38: 5 | AB38: 8 | AC38: 0 | AD38: 0 | AE38: 4 | AF38: 3 | AG38: 12 | AH38: 6.8 | AI38: -18
A39: 33 | B39: 45672 | C39: No Luka | D39: REGULAR | E39: LAL | G39: MIA | H39: W | I39: 117-108 | J39: * | K39: 35.233333 | L39: 5 | M39: 9 | N39: 0.556 | O39: 2 | P39: 3 | Q39: 0.667 | R39: 3 | S39: 6 | T39: 0.5 | U39: 0.667 | V39: 2 | W39: 2 | X39: 1 | Y39: 0 | Z39: 3 | AA39: 3 | AB39: 14 | AC39: 3 | AD39: 0 | AE39: 1 | AF39: 4 | AG39: 14 | AH39: 20.8 | AI39: 14
A40: 34 | B40: 45674 | C40: No Luka | D40: REGULAR | E40: LAL | G40: BRK | H40: W | I40: 102-101 | J40: * | K40: 37.083333 | L40: 13 | M40: 23 | N40: 0.565 | O40: 4 | P40: 8 | Q40: 0.5 | R40: 9 | S40: 15 | T40: 0.6 | U40: 0.652 | V40: 8 | W40: 8 | X40: 1 | Y40: 0 | Z40: 3 | AA40: 3 | AB40: 3 | AC40: 2 | AD40: 1 | AE40: 0 | AF40: 2 | AG40: 38 | AH40: 32 | AI40: 1
...

Sheet TEAM AND OPPONENT STATS
A1: TEAM AND OPPONENT STATS | C1: Ranks are per game (except for MP, which are total) and sorted descending (except for TOV and PF); opponents ranked are flipped; year/year calculations are also per game
A3: TEAM STATS | B3: G | C3: MP | D3: FG | E3: FGA | F3: FG% | G3: 3P | H3: 3PA | I3: 3P% | J3: 2P | K3: 2PA | L3: 2P% | M3: FT | N3: FTA | O3: FT% | P3: ORB | Q3: DRB | R3: TRB | S3: AST | T3: STL | U3: BLK | V3: TOV | W3: PF | X3: PTS
A4: Team | B4: 82 | C4: 19730 | D4: 3356 | E4: 7007 | F4: 0.479 | G4: 1092 | H4: 2981 | I4: 0.366 | J4: 2264 | K4: 4026 | L4: 0.562 | M4: 1494 | N4: 1902 | O4: 0.785 | P4: 792 | Q4: 2687 | R4: 3479 | S4: 2131 | T4: 633 | U4: 367 | V4: 1145 | W4: 1415 | X4: 9298
A5: Team/G | C5: 240.6 | D5: 40.9 | E5: 85.5 | F5: 0.479 | G5: 13.3 | H5: 36.4 | I5: 0.366 | J5: 27.6 | K5: 49.1 | L5: 0.562 | M5: 18.2 | N5: 23.2 | O5: 0.785 | P5: 9.7 | Q5: 32.8 | R5: 42.4 | S5: 26 | T5: 7.7 | U5: 4.5 | V5: 14 | W5: 17.3 | X5: 113.4
A6: Lg Rank | C6: 23 | D6: 20 | E6: 30 | F6: 9 | G6: 15 | H6: 19 | I6: 14 | J6: 19 | K6: 24 | L6: 5 | M6: 2 | N6: 3 | O6: 13 | P6: 27 | Q6: 20 | R6: 26 | S6: 18 | T6: 22 | U6: 22 | V6: 12 | W6: 5 | X6: 19
A7: Year/Year | C7: -0.006 | D7: -0.063 | E7: -0.024 | F7: -0.02 | G7: 0.127 | H7: 0.159 | I7: -0.01 | J7: -0.133 | K7: -0.126 | L7: -0.005 | M7: -0.036 | N7: -0.041 | O7: 0.004 | P7: 0.172 | Q7: -0.06 | R7: -0.016 | S7: -0.089 | T7: 0.046 | U7: -0.19 | V7: -0.001 | W7: 0.103 | X7: -0.039
A9: OPPONENT STATS | B9: G | C9: MP | D9: FG | E9: FGA | F9: FG% | G9: 3P | H9: 3PA | I9: 3P% | J9: 2P | K9: 2PA | L9: 2P% | M9: FT | N9: FTA | O9: FT% | P9: ORB | Q9: DRB | R9: TRB | S9: AST | T9: STL | U9: BLK | V9: TOV | W9: PF | X9: PTS
A10: Opponent | B10: 82 | C10: 19730 | D10: 3392 | E10: 7319 | F10: 0.463 | G10: 1112 | H10: 3124 | I10: 0.356 | J10: 2280 | K10: 4195 | L10: 0.544 | M10: 1302 | N10: 1680 | O10: 0.775 | P10: 919 | Q10: 2609 | R10: 3528 | S10: 2236 | T10: 673 | U10: 344 | V10: 1121 | W10: 1576 | X10: 9198
A11: Opponent/G | C11: 240.6 | D11: 41.4 | E11: 89.3 | F11: 0.463 | G11: 13.6 | H11: 38.1 | I11: 0.356 | J11: 27.8 | K11: 51.2 | L11: 0.544 | M11: 15.9 | N11: 20.5 | O11: 0.775 | P11: 11.2 | Q11: 31.8 | R11: 43 | S11: 27.3 | T11: 8.2 | U11: 4.2 | V11: 13.7 | W11: 19.2 | X11: 112.2
A12: Lg Rank | C12: 23 | D12: 13 | E12: 16 | F12: 10 | G12: 15 | H12: 18 | I12: 10 | J12: 15 | K12: 13 | L12: 13 | M12: 7 | N12: 7 | O12: 10 | P12: 16 | Q12: 5 | R12: 9 | S12: 22 | T12: 17 | U12: 4 | V12: 20 | W12: 6 | X12: 10
A13: Year/Year | C13: -0.006 | D13: -0.069 | E13: -0.048 | F13: -0.01 | G13: -0.05 | H13: 0.005 | I13: -0.02 | J13: -0.078 | K13: -0.084 | L13: 0.003 | M13: 0.109 | N13: 0.138 | O13: -0.02 | P13: 0.029 | Q13: -0.04 | R13: -0.023 | S13: -0.035 | T13: 0 | U13: -0.118 | V13: 0.019 | W13: -0.027 | X13: -0.045

Sheet Minny_Stats_2025_PLAYOFFSvsLake
A1: TOTALS | V1: SHOOTING | Y1: PER GAME
A2: Rk | B2: Player | C2: Age | D2: G | E2: GS | F2: MP | G2: FG | H2: FGA | I2: 3P | J2: 3PA | K2: FT | L2: FTA | M2: ORB | N2: DRB | O2: TRB | P2: AST | Q2: STL | R2: BLK | S2: TOV | T2: PF | U2: PTS | V2: FG% | W2: 3P% | X2: FT% | Y2: MP2 | Z2: PTS3 | AA2: TRB4 | AB2: AST5 | AC2: STL6 | AD2: BLK7
A3: 1 | B3: Anthony Edwards | C3: 23 | D3: 5 | E3: 5 | F3: 205 | G3: 47 | H3: 112 | I3: 16 | J3: 48 | K3: 24 | L3: 31 | M3: 11 | N3: 31 | O3: 42 | P3: 31 | Q3: 6 | R3: 2 | S3: 6 | T3: 10 | U3: 134 | V3: 0.42 | W3: 0.333 | X3: 0.774 | Y3: 41 | Z3: 26.8 | AA3: 8.4 | AB3: 6.2 | AC3: 1.2 | AD3: 0.4
A4: 2 | B4: Julius Randle | C4: 30 | D4: 5 | E4: 5 | F4: 189 | G4: 38 | H4: 79 | I4: 11 | J4: 28 | K4: 26 | L4: 31 | M4: 8 | N4: 18 | O4: 26 | P4: 22 | Q4: 4 | R4: 1 | S4: 13 | T4: 19 | U4: 113 | V4: 0.481 | W4: 0.393 | X4: 0.839 | Y4: 37.8 | Z4: 22.6 | AA4: 5.2 | AB4: 4.4 | AC4: 0.8 | AD4: 0.2
A5: 3 | B5: Jaden McDaniels | C5: 24 | D5: 5 | E5: 5 | F5: 166 | G5: 35 | H5: 61 | I5: 6 | J5: 16 | K5: 11 | L5: 13 | M5: 12 | N5: 20 | O5: 32 | P5: 7 | Q5: 5 | R5: 1 | S5: 4 | T5: 20 | U5: 87 | V5: 0.574 | W5: 0.375 | X5: 0.846 | Y5: 33.2 | Z5: 17.4 | AA5: 6.4 | AB5: 1.4 | AC5: 1 | AD5: 0.2
A6: 4 | B6: Naz Reid | C6: 25 | D6: 5 | E6: 0 | F6: 120 | G6: 20 | H6: 38 | I6: 11 | J6: 22 | K6: 7 | L6: 11 | M6: 4 | N6: 15 | O6: 19 | P6: 7 | Q6: 3 | R6: 5 | S6: 5 | T6: 12 | U6: 58 | V6: 0.526 | W6: 0.5 | X6: 0.636 | Y6: 24.1 | Z6: 11.6 | AA6: 3.8 | AB6: 1.4 | AC6: 0.6 | AD6: 1
A7: 5 | B7: Rudy Gobert | C7: 32 | D7: 5 | E7: 5 | F7: 143 | G7: 16 | H7: 28 | I7: 0 | J7: 0 | K7: 9 | L7: 18 | M7: 19 | N7: 30 | O7: 49 | P7: 2 | Q7: 5 | R7: 4 | S7: 4 | T7: 13 | U7: 41 | V7: 0.571 | X7: 0.5 | Y7: 28.6 | Z7: 8.2 | AA7: 9.8 | AB7: 0.4 | AC7: 1 | AD7: 0.8
